Workbook

Sheet README
B1: Pond IMTA vs fish polyculture: LCA results and circular KPI decision tool
B2: Source: INTEGRATE deliverable PI05#3 (IPMA & CTAQUA, 2020) · KPI layer by K. M. Chougule
B4: 1 What this workbook does
B6: It takes the inventory and the life cycle impact results of the INTEGRATE pond study and turns them into a KPI decision tool: 13 KPIs (7 environmental, 6 circularity) with targets and a pass / fail score for three farm designs. Every result is a live formula: change a yellow input and the KPIs, charts and tables update.
B7: Functional unit: 1 tonne of aquatic product (fish + oyster flesh) at the farm gate, one production cycle. Macroalgae are a co-product outside the functional unit.
B9: 2 Systems compared
B11: Code | C11: System | D11: Site | F11: Species and role
B12: SI-IMTA | C12: Semi-intensive pond IMTA | D12: IPMA research station, Olhao, Portugal | F12: Meagre, white seabream, mullet + oysters + macroalgae (Ulva)
B13: SE-IMTA | C13: Semi-extensive pond IMTA | D13: Estero Natural, Cadiz, Spain | F13: Gilthead seabream + oysters; macroalgae pond fed by the fishpond outflow; tidal water exchange
B14: SI-POLY | C14: Semi-intensive fish polyculture | D14: IPMA research station, Olhao, Portugal | F14: Meagre + gilthead seabream, fish only. Conventional baseline
B16: 3 Key results (live, per tonne of fish + oyster)
B18: Indicator | D18: Semi-intensive pond IMTA | E18: Semi-extensive pond IMTA | F18: Semi-intensive fish polyculture
B19: KPI targets met (of 13) | D19: ='KPI framework'!J22 -> 9 / 13 | E19: ='KPI framework'!K22 -> 12 / 13 | F19: ='KPI framework'!L22 -> 0 / 13
B20: Global warming, kg CO2-eq/t | D20: =Comparison!C5 -> 2801 | E20: =Comparison!D5 -> 1255 | F20: =Comparison!E5 -> 2836
B21: Eutrophication, kg PO4-eq/t | D21: =Comparison!C9 -> 26 | E21: =Comparison!D9 -> 2 | F21: =Comparison!E9 -> 61
B22: Land competition, m2a/t | D22: =Comparison!C10 -> 2946 | E22: =Comparison!D10 -> 4885 | F22: =Comparison!E10 -> 2379
B23: Water dependence, m3/t | D23: =Comparison!C11 -> 163840 | E23: =Comparison!D11 -> 115691 | F23: =Comparison!E11 -> 393002
B24: Nitrogen use efficiency | D24: ='Nutrient balance'!C13 -> 0.46975888 | E24: ='Nutrient balance'!D13 -> 1.1060393 | F24: ='Nutrient balance'!E13 -> 0.20175724
B25: Net N released, kg N/t (minus = uptake) | D25: ='Nutrient balance'!C14 -> 54.738487 | E25: ='Nutrient balance'!D14 -> -3.7987421 | F25: ='Nutrient balance'!E14 -> 95.929607
B26: Semi-extensive IMTA scores best on 6 of 7 impacts; both IMTA systems need more land than the fish-only pond.
B28: 4 Tabs (click a name to open it)
B30: Tab | C30: What you find there | F30: Type
B31: Goal & scope | C31: Functional unit, boundary, software, impact categories, allocation | F31: Reference
B32: Flow diagrams | C32: How the fish waste is used in each system, with the flows | F32: Pictures + data
B33: Metadata | C33: Dataset description in the LCIS2024 structure | F33: Reference
B34: Inventory | C34: Table 4 of the report per pond and cycle (yellow), scaled to 1 t of product | F34: Input + calculation
B35: Nutrient balance | C35: N and P from feed to fish + oysters, macroalgae and water (Table 5) | F35: Input + calculation
B36: LCI per tonne | C36: Foreground inventory for one functional unit, grouped into inputs and outputs | F36: Calculation
B37: LCIA (Annex 1) | C37: Impacts per tonne for 11 processes and 7 categories, with shares | F37: Input + calculation
B38: Contribution analysis | C38: Share of each process in each impact (heatmap) and contribution charts | F38: Calculation + charts
B39: Comparison | C39: Totals side by side and change against the fish-only pond | F39: Calculation + chart
B40: KPI framework | C40: 13 KPIs with targets and pass / fail; the improvement target is in F5 | F40: Input + calculation
B41: Dashboard | C41: Score per system and two summary charts | F41: Results + charts
... B45: Sources | C45: Report, method references and publications | F45: Reference
B47: 5 Colour code
B49: 1888 | C49: Input from the report. You can change it.
B50: =B49*2 -> 3776 | C50: Formula. Do not type over it.
B51: ✓ | C51: KPI target met
B52: ✗ | C52: KPI target not met
B54: 6 Things to try
...

Sheet Goal & scope
A1: Life cycle assessment of pond IMTA and fish polyculture - goal and scope (ISO 14040/44)
A2: Source: INTEGRATE deliverable PI05#3 (IPMA & CTAQUA, 2020)
A4: Item | B4: Choice in the study | C4: Note
A5: Goal | B5: Compare the potential environmental impacts of semi-intensive and semi-extensive pond IMTA with a conventional semi-intensive fishpond polyculture. | C5: INTEGRATE project (Interreg Atlantic Area, EAPA_232/2016), WP5 Action 2
A6: Functional unit | B6: 1 tonne of aquatic product (fish + oyster flesh weight gain) at the farm gate, one production cycle | C6: Macroalgae are an associated downstream product and are not part of the functional unit
A7: System boundary | B7: Farm operation plus production of inputs: fry and oyster spat, feeds, energy, equipment, buildings, vehicles, chemicals, transport; emissions from uneaten feed and excretion | C7: Packaging and transport to the retailer excluded (not full cradle-to-gate)
A8: Allocation | B8: None between fish and oysters (mass sum); infrastructure, vehicles and electricity allocated by production-pond area / total pond area | C8: See Hala, Chougule et al. (2024) for why allocation is a key IMTA challenge
A9: Nutrient emissions | B9: Nutrient balance: N and P in feed minus N and P retained in harvested biomass (Cho & Kaushik 1990) | C9: Table 5
A10: Software | B10: Piscentool (Excel interface, project Piscenlit; Wilfart et al. 2012), SimaPro background | C10: Fry: carp-fry LCA profile used as default
A11: Impact categories | B11: GW kg CO2-eq; TCED MJ-eq; NPPU kg C; Acidification kg SO2-eq; Eutrophication kg PO4-eq; Land competition m2a; Water dependence m3 | C11: CML-type midpoints with the aquaculture-specific NPPU and WD
A12: Data | B12: Primary data from daily farm records (water renewal, aeration, feed, mortality), feed supplier data, facility records | C12: Experimental-scale ponds (665-1,700 m2)
A13: Baseline | B13: Semi-intensive fishpond polyculture (fish only) | C13: Annex 1 labels it 'Semi-intensive MONO'

Sheet Flow diagrams
A1: Flow diagrams - how the fish waste is used in each system (per pond and production cycle)
A2: Source: INTEGRATE deliverable PI05#3 (IPMA & CTAQUA, 2020)
A3: Diagrams from make_flow.py (static). The table next to each one is live: it reads the Inventory and Nutrient balance tabs.
A5: Semi-intensive pond IMTA
P6: Data: Semi-intensive pond IMTA, one pond and cycle
P7: Flow | Q7: Value | R7: Unit
P8: Fish feed | Q8: =Inventory!C6 -> 1888 | R8: kg
P9: N in feed | Q9: ='Nutrient balance'!C8 -> 126.8736 | R9: kg N
P10: Fry + oyster spat stocked | Q10: =Inventory!C8+Inventory!C9 -> 682.5 | R10: kg
P11: Seawater | Q11: =Inventory!C7 -> 101110 | R11: m3
P12: Fish gained | Q12: =Inventory!C18 -> 1099 | R12: kg
P13: Oyster flesh gained | Q13: =Inventory!C19 -> 130 | R13: kg
P14: Macroalgae harvest | Q14: =Inventory!C20 -> 1224 | R14: kg
P15: N in fish + oysters | Q15: ='Nutrient balance'!C9 -> 29 | R15: kg N
P16: N in macroalgae | Q16: ='Nutrient balance'!C10 -> 30.6 | R16: kg N
P17: N in products | Q17: ='Nutrient balance'!C9+'Nutrient balance'!C10 -> 59.6 | R17: kg N
P18: N released (Table 5; minus = net uptake) | Q18: ='Nutrient balance'!C12 -> 67.2 | R18: kg N
P19: N use efficiency | Q19: ='Nutrient balance'!C13 -> 0.46975888 | R19: %
A32: Semi-extensive pond IMTA
P33: Data: Semi-extensive pond IMTA, one pond and cycle
P34: Flow | Q34: Value | R34: Unit
P35: Fish feed | Q35: =Inventory!D6 -> 89 | R35: kg
P36: N in feed | Q36: ='Nutrient balance'!D8 -> 5.696 | R36: kg N
P37: Fry + oyster spat stocked | Q37: =Inventory!D8+Inventory!D9 -> 59.4 | R37: kg
P38: Seawater | Q38: =Inventory!D7 -> 7185 | R38: m3
P39: Fish gained | Q39: =Inventory!D18 -> 65 | R39: kg
P40: Oyster flesh gained | Q40: =Inventory!D19 -> 94 | R40: kg
P41: Macroalgae harvest | Q41: =Inventory!D20 -> 35400 | R41: kg
P42: N in fish + oysters | Q42: ='Nutrient balance'!D9 -> 4.5 | R42: kg N
P43: N in macroalgae | Q43: ='Nutrient balance'!D10 -> 1.8 | R43: kg N
P44: N in products | Q44: ='Nutrient balance'!D9+'Nutrient balance'!D10 -> 6.3 | R44: kg N
P45: N released (Table 5; minus = net uptake) | Q45: ='Nutrient balance'!D12 -> -0.5 | R45: kg N
P46: N use efficiency | Q46: ='Nutrient balance'!D13 -> 1.1060393 | R46: %
A59: Semi-intensive fish polyculture
P60: Data: Semi-intensive fish polyculture, one pond and cycle
P61: Flow | Q61: Value | R61: Unit
P62: Fish feed | Q62: =Inventory!E6 -> 10975 | R62: kg
P63: N in feed | Q63: ='Nutrient balance'!E8 -> 737.52 | R63: kg N
P64: Fry + oyster spat stocked | Q64: =Inventory!E8+Inventory!E9 -> 91 | R64: kg
P65: Seawater | Q65: =Inventory!E7 -> 1201764 | R65: m3
...

Sheet Metadata
A1: Metadata (LCIS2024 structure, Nair, Chougule et al. 2025)
A2: Source: INTEGRATE deliverable PI05#3 (IPMA & CTAQUA, 2020)
A4: Element | B4: Label | C4: Value
A5: Dataset | B5: Name | C5: imta-integrate-lci
A6: Dataset | B6: Version | C6: 1.0.0
A7: Dataset | B7: UDI | C7: 53eb108d-c771-575e-ac70-d99573e5655b
A8: Dataset | B8: Description | C8: Foreground LCI and LCIA results of three earthen-pond aquaculture systems from INTEGRATE deliverable PI05#3
A9: Dataset | B9: Functional unit | C9: 1 t aquatic product (fish + oyster flesh) at farm gate
A10: Dataset | B10: Region | C10: Portugal (Olhao, Ria Formosa) and Spain (Cadiz)
A11: Dataset | B11: Time period | C11: 2017-2019 (one production cycle per system)
A12: Source | B12: Report | C12: LCA of aquaculture systems: comparison between semi-intensive/extensive pond IMTA and semi-intensive traditional fishpond production. Deliverable PI05#3, submitted 23/07/2020
A13: Source | B13: Lead / contributing partners | C13: IPMA; IPMA and CTAQUA
A14: Source | B14: Software | C14: Piscentool
A15: Licence | B15: Data | C15: Report data belong to the INTEGRATE partners; KPI layer CC BY 4.0
... A17: Glossary | B17: Abbreviations | C17: IMTA integrated multi-trophic aquaculture; POLY polyculture; SI semi-intensive; SE semi-extensive; FCR feed conversion ratio; NPPU net primary production use; TCED total cumulative energy demand; WD water dependence; LC land competition

Sheet Inventory
A1: Inventory - Table 4 of the report (per production pond and cycle) and scaling to the functional unit
A2: Source: INTEGRATE deliverable PI05#3 (IPMA & CTAQUA, 2020)
A4: Parameter | B4: Unit | C4: Semi-intensive pond IMTA | D4: Semi-extensive pond IMTA | E4: Semi-intensive fish polyculture | F4: Source / note
A5: cycle length | B5: months | C5: 5.3 | D5: 8.5 | E5: 26 | F5: Table 4
A6: feed | B6: kg | C6: 1888 | D6: 89 | E6: 10975 | F6: Table 4
A7: seawater used | B7: m3 | C7: 101110 | D7: 7185 | E7: 1201764 | F7: Table 4
A8: fish stocked | B8: kg | C8: 677 | D8: 45 | E8: 91 | F8: Table 4 (initial fish biomass)
A9: oyster stocked | B9: kg flesh | C9: 5.5 | D9: 14.4 | E9: 0 | F9: Table 4 (initial oyster flesh biomass)
A10: diet protein | B10: % | C10: 42 | D10: 40 | E10: 42 | F10: Table 4
A11: diet lipid | B11: % | C11: 18 | D11: 18 | E11: 18 | F11: Table 4
A12: diet cellulose | B12: % | C12: 3 | D12: 3.5 | E12: 3 | F12: Table 4
A13: diet ash | B13: % | C13: 9 | D13: 9 | E13: 9 | F13: Table 4
A14: diet phosphorus | B14: % | C14: 1.4 | D14: 1.3 | E14: 1.4 | F14: Table 4
A15: farm area | B15: m2 | C15: 90000 | D15: 285000 | E15: 90000 | F15: Table 4
A16: farm pond area | B16: m2 | C16: 23600 | D16: 200000 | E16: 23600 | F16: Table 4
... A21: fcr reported | B21: - | C21: 1.72 | D21: 0.56 | E21: 1.79 | F21: Table 4
A23: Scaling to the functional unit (formulas)
A24: fish + oyster flesh gain | B24: kg | C24: =C18+C19 -> 1229 | D24: =D18+D19 -> 159 | E24: =E18+E19 -> 6137 | F24: functional unit basis
A25: scaling factor to 1 t | B25: - | C25: =1000/C24 -> 0.81366965 | D25: =1000/D24 -> 6.2893082 | E25: =1000/E24 -> 0.16294606 | F25: 1,000 kg / product
A26: FCR, feed / fish gain | B26: kg/kg | C26: =C6/C18 -> 1.7179254 | D26: =D6/D18 -> 1.3692308 | E26: =E6/E18 -> 1.7883331 | F26: compare with reported FCR
A27: feed / (fish + oyster gain) | B27: kg/kg | C27: =C6/C24 -> 1.5362083 | D27: =D6/D24 -> 0.55974843 | E27: =E6/E24 -> 1.7883331 | F27: explains the reported 0.56 of the semi-extensive IMTA
A28: farm area allocated to the pond x cycle | B28: m2a | C28: =C15*C17/C16*C5/12 -> 1179.0254 | D28: =D15*D17/D16*D5/12 -> 671.23438 | E28: =E15*E17/E16*E5/12 -> 14046.61 | F28: report rule: pond area / total pond area

Sheet Nutrient balance
A1: Nutrient balance - where the N and P in the feed go (per pond and cycle, Table 5)
A2: Source: INTEGRATE deliverable PI05#3 (IPMA & CTAQUA, 2020)
A4: Item | B4: Unit | C4: Semi-intensive pond IMTA | D4: Semi-extensive pond IMTA | E4: Semi-intensive fish polyculture | F4: Source / note
A5: protein to N factor | C5: 6.25 | F5: N = protein / 6.25
A7: Nitrogen (kg N)
A8: N in feed | B8: kg | C8: =Inventory!C6*Inventory!C10/100/$C$5 -> 126.8736 | D8: =Inventory!D6*Inventory!D10/100/$C$5 -> 5.696 | E8: =Inventory!E6*Inventory!E10/100/$C$5 -> 737.52 | F8: formula from feed and recipe
A9: N in fish + oysters | B9: kg | C9: 29 | D9: 4.5 | E9: 148.8 | F9: Table 5
A10: N in macroalgae | B10: kg | C10: 30.6 | D10: 1.8 | E10: 0 | F10: Table 5
A11: N released to water (net) | B11: kg | C11: =C8-C9-C10 -> 67.2736 | D11: =D8-D9-D10 -> -0.604 | E11: =E8-E9-E10 -> 588.72 | F11: negative = net uptake from the environment
A12: N rejection reported | B12: kg | C12: 67.2 | D12: -0.5 | E12: 588.7 | F12: Table 5, for comparison
A13: N use efficiency | B13: % | C13: =(C9+C10)/C8 -> 0.46975888 | D13: =(D9+D10)/D8 -> 1.1060393 | E13: =(E9+E10)/E8 -> 0.20175724 | F13: N or P in all products / N or P in feed
A14: N released per t product | B14: kg | C14: =C11*Inventory!C25 -> 54.738487 | D14: =D11*Inventory!D25 -> -3.7987421 | E14: =E11*Inventory!E25 -> 95.929607 | F14: kg per tonne fish + oyster
A16: Phosphorus (kg P)
A17: P in feed | B17: kg | C17: =Inventory!C6*Inventory!C14/100 -> 26.432 | D17: =Inventory!D6*Inventory!D14/100 -> 1.157 | E17: =Inventory!E6*Inventory!E14/100 -> 153.65 | F17: formula from feed and recipe
A18: P in fish + oysters | B18: kg | C18: 5.9 | D18: 1 | E18: 25 | F18: Table 5
A19: P in macroalgae | B19: kg | C19: 2.6 | D19: 0.1 | E19: 0 | F19: Table 5
A20: P released to water (net) | B20: kg | C20: =C17-C18-C19 -> 17.932 | D20: =D17-D18-D19 -> 0.057 | E20: =E17-E18-E19 -> 128.65 | F20: negative = net uptake from the environment
A21: P rejection reported | B21: kg | C21: 18 | D21: 0 | E21: 128.7 | F21: Table 5, for comparison
A22: P use efficiency | B22: % | C22: =(C18+C19)/C17 -> 0.3215799 | D22: =(D18+D19)/D17 -> 0.95073466 | E22: =(E18+E19)/E17 -> 0.16270745 | F22: N or P in all products / N or P in feed
A23: P released per t product | B23: kg | C23: =C20*Inventory!C25 -> 14.590724 | D23: =D20*Inventory!D25 -> 0.35849057 | E23: =E20*Inventory!E25 -> 20.963011 | F23: kg per tonne fish + oyster

Sheet LCI per tonne
A1: Foreground LCI per functional unit (1 t fish + oyster flesh) - inputs and outputs, all formulas
A2: Source: INTEGRATE deliverable PI05#3 (IPMA & CTAQUA, 2020)
A3: Table 1 INPUTS = what the farm takes in. Table 2 OUTPUTS = what leaves the farm. Amounts per tonne of fish + oyster flesh; all values are formulas on the Inventory and Nutrient balance tabs.
A5: 1 INPUTS - what the farm takes in
A6: Flow (fp_name) | B6: Kind | C6: Semi-intensive pond IMTA | D6: Semi-extensive pond IMTA | E6: Semi-intensive fish polyculture | F6: Unit | G6: Comment
A7: From the technosphere (products of other processes)
A8: compound fish feed | B8: technosphere | C8: =Inventory!C6*Inventory!C25 -> 1536.2083 | D8: =Inventory!D6*Inventory!D25 -> 559.74843 | E8: =Inventory!E6*Inventory!E25 -> 1788.3331 | F8: kg | G8: 40-42 % protein
A9: fish fry / fingerlings | B9: technosphere | C9: =Inventory!C8*Inventory!C25 -> 550.85435 | D9: =Inventory!D8*Inventory!D25 -> 283.01887 | E9: =Inventory!E8*Inventory!E25 -> 14.828092 | F9: kg | G9: carp-fry proxy in Piscentool
A10: oyster spat (flesh) | B10: technosphere | C10: =Inventory!C9*Inventory!C25 -> 4.4751831 | D10: =Inventory!D9*Inventory!D25 -> 90.566038 | E10: =Inventory!E9*Inventory!E25 -> 0 | F10: kg
A11: From nature (resources)
A12: seawater, pumped or tidal | B12: resource | C12: =Inventory!C7*Inventory!C25 -> 82270.138 | D12: =Inventory!D7*Inventory!D25 -> 45188.679 | E12: =Inventory!E7*Inventory!E25 -> 195822.71 | F12: m3 | G12: equals Water consumption in Annex 1
A13: land, farm area allocated to the pond | B13: resource | C13: =Inventory!C28*Inventory!C25 -> 959.3372 | D13: =Inventory!D28*Inventory!D25 -> 4221.5998 | E13: =Inventory!E28*Inventory!E25 -> 2288.8399 | F13: m2a | G13: compare Direct activity, Land competition
A14: Included in the impact results, but the report gives no quantities
A15: electricity / fuel for pumping and aeration | B15: technosphere | C15: n/a | D15: n/a | E15: n/a | G15: only its impacts are reported: process 'Energy consumption' in LCIA (Annex 1)
A16: equipment (pumps, aerators, nets) | B16: technosphere | C16: n/a | D16: n/a | E16: n/a | G16: only its impacts are reported: process 'Equipment' in LCIA (Annex 1)
A17: buildings | B17: technosphere | C17: n/a | D17: n/a | E17: n/a | G17: only its impacts are reported: process 'Building impact' in LCIA (Annex 1)
A18: vehicles | B18: technosphere | C18: n/a | D18: n/a | E18: n/a | G18: only its impacts are reported: process 'Vehicle' in LCIA (Annex 1)
A19: chemical products | B19: technosphere | C19: n/a | D19: n/a | E19: n/a | G19: only its impacts are reported: process 'Chemical products' in LCIA (Annex 1)
A20: transport of inputs | B20: technosphere | C20: n/a | D20: n/a | E20: n/a | G20: only its impacts are reported: process 'Transports' in LCIA (Annex 1)
A23: 2 OUTPUTS - what leaves the farm
A24: Flow (fp_name) | B24: Kind | C24: Semi-intensive pond IMTA | D24: Semi-extensive pond IMTA | E24: Semi-intensive fish polyculture | F24: Unit | G24: Comment
A25: Products (the functional unit)
A26: aquatic product, fish + oyster flesh, at farm gate | B26: reference product | C26: =1 -> 1 | D26: =1 -> 1 | E26: =1 -> 1 | F26: t | G26: functional unit
A27: fish, live weight gain | B27: product | C27: =Inventory!C18*Inventory!C25 -> 894.22295 | D27: =Inventory!D18*Inventory!D25 -> 408.80503 | E27: =Inventory!E18*Inventory!E25 -> 1000 | F27: kg | G27: part of the 1 t
A28: oyster flesh, weight gain | B28: product | C28: =Inventory!C19*Inventory!C25 -> 105.77705 | D28: =Inventory!D19*Inventory!D25 -> 591.19497 | E28: =Inventory!E19*Inventory!E25 -> 0 | F28: kg | G28: part of the 1 t
A29: Co-product (outside the functional unit)
A30: macroalgae, biomass gain | B30: co-product | C30: =Inventory!C20*Inventory!C25 -> 995.93165 | D30: =Inventory!D20*Inventory!D25 -> 222641.51 | E30: =Inventory!E20*Inventory!E25 -> 0 | F30: kg | G30: harvested; not allocated any burden
A31: Emissions to nature
A32: nitrogen, to water (net) | B32: emission | C32: ='Nutrient balance'!C14 -> 54.738487 | D32: ='Nutrient balance'!D14 -> -3.7987421 | E32: ='Nutrient balance'!E14 -> 95.929607 | F32: kg N | G32: negative = net uptake from the water
A33: phosphorus, to water (net) | B33: emission | C33: ='Nutrient balance'!C23 -> 14.590724 | D33: ='Nutrient balance'!D23 -> 0.35849057 | E33: ='Nutrient balance'!E23 -> 20.963011 | F33: kg P | G33: negative = net uptake from the water

Sheet LCIA (Annex 1)
A1: Life cycle impact assessment per tonne of fish + oyster - Annex 1 of the report (Piscentool)
A2: Source: INTEGRATE deliverable PI05#3 (IPMA & CTAQUA, 2020)
A3: Amounts are as printed (rounded to whole units); shares are calculated from the reported total.
A4: Process | B4: Unit | C4: Semi-intensive pond IMTA | D4: Semi-extensive pond IMTA | E4: Semi-intensive fish polyculture | G4: Share SI-IMTA | H4: Share SE-IMTA | I4: Share POLY
A5: GW - Global warming (GWP100) (kg CO2-eq)
A6: Building impact | B6: kg CO2-eq | C6: 137 | D6: 12 | E6: 13 | G6: =IF(C$18=0,0,C6/C$18) -> 0.048911103 | H6: =IF(D$18=0,0,D6/D$18) -> 0.009561753 | I6: =IF(E$18=0,0,E6/E$18) -> 0.004583921
A7: Energy consumption | B7: kg CO2-eq | C7: 330 | D7: 6 | E7: 474 | G7: =IF(C$18=0,0,C7/C$18) -> 0.11781507 | H7: =IF(D$18=0,0,D7/D$18) -> 0.0047808765 | I7: =IF(E$18=0,0,E7/E$18) -> 0.16713681
A8: Water consumption | B8: kg CO2-eq | C8: 0 | D8: 0 | E8: 0 | G8: =IF(C$18=0,0,C8/C$18) -> 0 | H8: =IF(D$18=0,0,D8/D$18) -> 0 | I8: =IF(E$18=0,0,E8/E$18) -> 0
A9: Vehicle | B9: kg CO2-eq | C9: 32 | D9: 8 | E9: 80 | G9: =IF(C$18=0,0,C9/C$18) -> 0.011424491 | H9: =IF(D$18=0,0,D9/D$18) -> 0.006374502 | I9: =IF(E$18=0,0,E9/E$18) -> 0.028208745
A10: Rejects fish | B10: kg CO2-eq | C10: 0 | D10: 0 | E10: 0 | G10: =IF(C$18=0,0,C10/C$18) -> 0 | H10: =IF(D$18=0,0,D10/D$18) -> 0 | I10: =IF(E$18=0,0,E10/E$18) -> 0
A11: Chemical products | B11: kg CO2-eq | C11: 0 | D11: 30 | E11: 0 | G11: =IF(C$18=0,0,C11/C$18) -> 0 | H11: =IF(D$18=0,0,D11/D$18) -> 0.023904382 | I11: =IF(E$18=0,0,E11/E$18) -> 0
A12: Equipment | B12: kg CO2-eq | C12: 386 | D12: 228 | E12: 15 | G12: =IF(C$18=0,0,C12/C$18) -> 0.13780793 | H12: =IF(D$18=0,0,D12/D$18) -> 0.18167331 | I12: =IF(E$18=0,0,E12/E$18) -> 0.0052891396
A13: Fry | B13: kg CO2-eq | C13: 43 | D13: 29 | E13: 1 | G13: =IF(C$18=0,0,C13/C$18) -> 0.01535166 | H13: =IF(D$18=0,0,D13/D$18) -> 0.02310757 | I13: =IF(E$18=0,0,E13/E$18) -> 0.00035260931
A14: Feeds | B14: kg CO2-eq | C14: 1549 | D14: 733 | E14: 1873 | G14: =IF(C$18=0,0,C14/C$18) -> 0.55301678 | H14: =IF(D$18=0,0,D14/D$18) -> 0.58406375 | I14: =IF(E$18=0,0,E14/E$18) -> 0.66043724
A15: Transports | B15: kg CO2-eq | C15: 325 | D15: 208 | E15: 379 | G15: =IF(C$18=0,0,C15/C$18) -> 0.11602999 | H15: =IF(D$18=0,0,D15/D$18) -> 0.16573705 | I15: =IF(E$18=0,0,E15/E$18) -> 0.13363893
A16: Direct activity | B16: kg CO2-eq | C16: 0 | D16: 0 | E16: 0 | G16: =IF(C$18=0,0,C16/C$18) -> 0 | H16: =IF(D$18=0,0,D16/D$18) -> 0 | I16: =IF(E$18=0,0,E16/E$18) -> 0
A17: Sum of processes | C17: =SUM(C6:C16) -> 2802 | D17: =SUM(D6:D16) -> 1254 | E17: =SUM(E6:E16) -> 2835
A18: Total (reported) | B18: kg CO2-eq | C18: 2801 | D18: 1255 | E18: 2836
A20: TCED - Total cumulative energy demand (MJ-eq)
A21: Building impact | B21: MJ-eq | C21: 2701 | D21: 240 | E21: 263 | G21: =IF(C$33=0,0,C21/C$33) -> 0.029968822 | H21: =IF(D$33=0,0,D21/D$33) -> 0.012567419 | I21: =IF(E$33=0,0,E21/E$33) -> 0.0026327117
A22: Energy consumption | B22: MJ-eq | C22: 45724 | D22: 82 | E22: 65724 | G22: =IF(C$33=0,0,C22/C$33) -> 0.50732855 | H22: =IF(D$33=0,0,D22/D$33) -> 0.0042938681 | I22: =IF(E$33=0,0,E22/E$33) -> 0.65791766
A23: Water consumption | B23: MJ-eq | C23: 0 | D23: 0 | E23: 0 | G23: =IF(C$33=0,0,C23/C$33) -> 0 | H23: =IF(D$33=0,0,D23/D$33) -> 0 | I23: =IF(E$33=0,0,E23/E$33) -> 0
A24: Vehicle | B24: MJ-eq | C24: 700 | D24: 150 | E24: 1749 | G24: =IF(C$33=0,0,C24/C$33) -> 0.0077668179 | H24: =IF(D$33=0,0,D24/D$33) -> 0.0078546369 | I24: =IF(E$33=0,0,E24/E$33) -> 0.017508033
A25: Rejects fish | B25: MJ-eq | C25: 0 | D25: 0 | E25: 0 | G25: =IF(C$33=0,0,C25/C$33) -> 0 | H25: =IF(D$33=0,0,D25/D$33) -> 0 | I25: =IF(E$33=0,0,E25/E$33) -> 0
A26: Chemical products | B26: MJ-eq | C26: 0 | D26: 664 | E26: 0 | G26: =IF(C$33=0,0,C26/C$33) -> 0 | H26: =IF(D$33=0,0,D26/D$33) -> 0.034769859 | I26: =IF(E$33=0,0,E26/E$33) -> 0
A27: Equipment | B27: MJ-eq | C27: 14023 | D27: 6248 | E27: 555 | G27: =IF(C$33=0,0,C27/C$33) -> 0.15559155 | H27: =IF(D$33=0,0,D27/D$33) -> 0.32717181 | I27: =IF(E$33=0,0,E27/E$33) -> 0.0055557224
A28: Fry | B28: MJ-eq | C28: 469 | D28: 316 | E28: 12 | G28: =IF(C$33=0,0,C28/C$33) -> 0.005203768 | H28: =IF(D$33=0,0,D28/D$33) -> 0.016547102 | I28: =IF(E$33=0,0,E28/E$33) -> 0.00012012373
A29: Feeds | B29: MJ-eq | C29: 21028 | D29: 7900 | E29: 25185 | G29: =IF(C$33=0,0,C29/C$33) -> 0.23331521 | H29: =IF(D$33=0,0,D29/D$33) -> 0.41367754 | I29: =IF(E$33=0,0,E29/E$33) -> 0.25210967
A30: Transports | B30: MJ-eq | C30: 5483 | D30: 3497 | E30: 6409 | G30: =IF(C$33=0,0,C30/C$33) -> 0.060836375 | H30: =IF(D$33=0,0,D30/D$33) -> 0.18311777 | I30: =IF(E$33=0,0,E30/E$33) -> 0.064156081
A31: Direct activity | B31: MJ-eq | C31: 0 | D31: 0 | E31: 0 | G31: =IF(C$33=0,0,C31/C$33) -> 0 | H31: =IF(D$33=0,0,D31/D$33) -> 0 | I31: =IF(E$33=0,0,E31/E$33) -> 0
A32: Sum of processes | C32: =SUM(C21:C31) -> 90128 | D32: =SUM(D21:D31) -> 19097 | E32: =SUM(E21:E31) -> 99897
A33: Total (reported) | B33: MJ-eq | C33: 90127 | D33: 19097 | E33: 99897
A35: NPPU - Net primary production use (kg C)
A36: Building impact | B36: kg C | C36: 0 | D36: 0 | E36: 0 | G36: =IF(C$48=0,0,C36/C$48) -> 0 | H36: =IF(D$48=0,0,D36/D$48) -> 0 | I36: =IF(E$48=0,0,E36/E$48) -> 0
A37: Energy consumption | B37: kg C | C37: 0 | D37: 0 | E37: 0 | G37: =IF(C$48=0,0,C37/C$48) -> 0 | H37: =IF(D$48=0,0,D37/D$48) -> 0 | I37: =IF(E$48=0,0,E37/E$48) -> 0
A38: Water consumption | B38: kg C | C38: 0 | D38: 0 | E38: 0 | G38: =IF(C$48=0,0,C38/C$48) -> 0 | H38: =IF(D$48=0,0,D38/D$48) -> 0 | I38: =IF(E$48=0,0,E38/E$48) -> 0
A39: Vehicle | B39: kg C | C39: 0 | D39: 0 | E39: 0 | G39: =IF(C$48=0,0,C39/C$48) -> 0 | H39: =IF(D$48=0,0,D39/D$48) -> 0 | I39: =IF(E$48=0,0,E39/E$48) -> 0
A40: Rejects fish | B40: kg C | C40: 0 | D40: 0 | E40: 0 | G40: =IF(C$48=0,0,C40/C$48) -> 0 | H40: =IF(D$48=0,0,D40/D$48) -> 0 | I40: =IF(E$48=0,0,E40/E$48) -> 0
A41: Chemical products | B41: kg C | C41: 0 | D41: 0 | E41: 0 | G41: =IF(C$48=0,0,C41/C$48) -> 0 | H41: =IF(D$48=0,0,D41/D$48) -> 0 | I41: =IF(E$48=0,0,E41/E$48) -> 0
A42: Equipment | B42: kg C | C42: 0 | D42: 0 | E42: 0 | G42: =IF(C$48=0,0,C42/C$48) -> 0 | H42: =IF(D$48=0,0,D42/D$48) -> 0 | I42: =IF(E$48=0,0,E42/E$48) -> 0
...

Sheet Contribution analysis
A1: Contribution analysis - which process drives which impact, per tonne of fish + oyster
A2: Source: INTEGRATE deliverable PI05#3 (IPMA & CTAQUA, 2020)
A3: All values are formulas on the LCIA (Annex 1) tab. Share = process / sum of the absolute process amounts, so a negative share is a removal (net nutrient uptake).
A5: 1 Share of each impact per process group (heatmap) and contribution chart per system
A7: Semi-intensive pond IMTA
A8: Process group | B8: GW | C8: TCED | D8: NPPU | E8: AP | F8: EP | G8: LC | H8: WD
A9: Feeds | B9: =IF(SUMPRODUCT(ABS('LCIA (Annex 1)'!C6:C16))=0,0,('LCIA (Annex 1)'!C14)/SUMPRODUCT(ABS('LCIA (Annex 1)'!C6:C16))) -> 0.55281941 | C9: =IF(SUMPRODUCT(ABS('LCIA (Annex 1)'!C21:C31))=0,0,('LCIA (Annex 1)'!C29)/SUMPRODUCT(ABS('LCIA (Annex 1)'!C21:C31))) -> 0.23331262 | D9: =IF(SUMPRODUCT(ABS('LCIA (Annex 1)'!C36:C46))=0,0,('LCIA (Annex 1)'!C44)/SUMPRODUCT(ABS('LCIA (Annex 1)'!C36:C46))) -> 0.99475091 | E9: =IF(SUMPRODUCT(ABS('LCIA (Annex 1)'!C51:C61))=0,0,('LCIA (Annex 1)'!C59)/SUMPRODUCT(ABS('LCIA (Annex 1)'!C51:C61))) -> 0.19047619 | F9: =IF(SUMPRODUCT(ABS('LCIA (Annex 1)'!C66:C76))=0,0,('LCIA (Annex 1)'!C74)/SUMPRODUCT(ABS('LCIA (Annex 1)'!C66:C76))) -> 0.30769231 | G9: =IF(SUMPRODUCT(ABS('LCIA (Annex 1)'!C81:C91))=0,0,('LCIA (Annex 1)'!C89)/SUMPRODUCT(ABS('LCIA (Annex 1)'!C81:C91))) -> 0.65919891 | H9: =IF(SUMPRODUCT(ABS('LCIA (Annex 1)'!C96:C106))=0,0,('LCIA (Annex 1)'!C104)/SUMPRODUCT(ABS('LCIA (Annex 1)'!C96:C106))) -> 0.00028686348
A10: Rejects fish (uneaten feed, excretion) | B10: =IF(SUMPRODUCT(ABS('LCIA (Annex 1)'!C6:C16))=0,0,('LCIA (Annex 1)'!C10)/SUMPRODUCT(ABS('LCIA (Annex 1)'!C6:C16))) -> 0 | C10: =IF(SUMPRODUCT(ABS('LCIA (Annex 1)'!C21:C31))=0,0,('LCIA (Annex 1)'!C25)/SUMPRODUCT(ABS('LCIA (Annex 1)'!C21:C31))) -> 0 | D10: =IF(SUMPRODUCT(ABS('LCIA (Annex 1)'!C36:C46))=0,0,('LCIA (Annex 1)'!C40)/SUMPRODUCT(ABS('LCIA (Annex 1)'!C36:C46))) -> 0 | E10: =IF(SUMPRODUCT(ABS('LCIA (Annex 1)'!C51:C61))=0,0,('LCIA (Annex 1)'!C55)/SUMPRODUCT(ABS('LCIA (Annex 1)'!C51:C61))) -> 0.5952381 | F10: =IF(SUMPRODUCT(ABS('LCIA (Annex 1)'!C66:C76))=0,0,('LCIA (Annex 1)'!C70)/SUMPRODUCT(ABS('LCIA (Annex 1)'!C66:C76))) -> 0.61538462 | G10: =IF(SUMPRODUCT(ABS('LCIA (Annex 1)'!C81:C91))=0,0,('LCIA (Annex 1)'!C85)/SUMPRODUCT(ABS('LCIA (Annex 1)'!C81:C91))) -> 0 | H10: =IF(SUMPRODUCT(ABS('LCIA (Annex 1)'!C96:C106))=0,0,('LCIA (Annex 1)'!C100)/SUMPRODUCT(ABS('LCIA (Annex 1)'!C96:C106))) -> 0
A11: Energy consumption | B11: =IF(SUMPRODUCT(ABS('LCIA (Annex 1)'!C6:C16))=0,0,('LCIA (Annex 1)'!C7)/SUMPRODUCT(ABS('LCIA (Annex 1)'!C6:C16))) -> 0.11777302 | C11: =IF(SUMPRODUCT(ABS('LCIA (Annex 1)'!C21:C31))=0,0,('LCIA (Annex 1)'!C22)/SUMPRODUCT(ABS('LCIA (Annex 1)'!C21:C31))) -> 0.50732292 | D11: =IF(SUMPRODUCT(ABS('LCIA (Annex 1)'!C36:C46))=0,0,('LCIA (Annex 1)'!C37)/SUMPRODUCT(ABS('LCIA (Annex 1)'!C36:C46))) -> 0 | E11: =IF(SUMPRODUCT(ABS('LCIA (Annex 1)'!C51:C61))=0,0,('LCIA (Annex 1)'!C52)/SUMPRODUCT(ABS('LCIA (Annex 1)'!C51:C61))) -> 0.047619048 | F11: =IF(SUMPRODUCT(ABS('LCIA (Annex 1)'!C66:C76))=0,0,('LCIA (Annex 1)'!C67)/SUMPRODUCT(ABS('LCIA (Annex 1)'!C66:C76))) -> 0.038461538 | G11: =IF(SUMPRODUCT(ABS('LCIA (Annex 1)'!C81:C91))=0,0,('LCIA (Annex 1)'!C82)/SUMPRODUCT(ABS('LCIA (Annex 1)'!C81:C91))) -> 0.0027155465 | H11: =IF(SUMPRODUCT(ABS('LCIA (Annex 1)'!C96:C106))=0,0,('LCIA (Annex 1)'!C97)/SUMPRODUCT(ABS('LCIA (Annex 1)'!C96:C106))) -> 0.00023193218
A12: Transports | B12: =IF(SUMPRODUCT(ABS('LCIA (Annex 1)'!C6:C16))=0,0,('LCIA (Annex 1)'!C15)/SUMPRODUCT(ABS('LCIA (Annex 1)'!C6:C16))) -> 0.11598858 | C12: =IF(SUMPRODUCT(ABS('LCIA (Annex 1)'!C21:C31))=0,0,('LCIA (Annex 1)'!C30)/SUMPRODUCT(ABS('LCIA (Annex 1)'!C21:C31))) -> 0.0608357 | D12: =IF(SUMPRODUCT(ABS('LCIA (Annex 1)'!C36:C46))=0,0,('LCIA (Annex 1)'!C45)/SUMPRODUCT(ABS('LCIA (Annex 1)'!C36:C46))) -> 0 | E12: =IF(SUMPRODUCT(ABS('LCIA (Annex 1)'!C51:C61))=0,0,('LCIA (Annex 1)'!C60)/SUMPRODUCT(ABS('LCIA (Annex 1)'!C51:C61))) -> 0.047619048 | F12: =IF(SUMPRODUCT(ABS('LCIA (Annex 1)'!C66:C76))=0,0,('LCIA (Annex 1)'!C75)/SUMPRODUCT(ABS('LCIA (Annex 1)'!C66:C76))) -> 0 | G12: =IF(SUMPRODUCT(ABS('LCIA (Annex 1)'!C81:C91))=0,0,('LCIA (Annex 1)'!C90)/SUMPRODUCT(ABS('LCIA (Annex 1)'!C81:C91))) -> 0.0013577733 | H12: =IF(SUMPRODUCT(ABS('LCIA (Annex 1)'!C96:C106))=0,0,('LCIA (Annex 1)'!C105)/SUMPRODUCT(ABS('LCIA (Annex 1)'!C96:C106))) -> 1.8310435e-05
A13: Equipment | B13: =IF(SUMPRODUCT(ABS('LCIA (Annex 1)'!C6:C16))=0,0,('LCIA (Annex 1)'!C12)/SUMPRODUCT(ABS('LCIA (Annex 1)'!C6:C16))) -> 0.13775874 | C13: =IF(SUMPRODUCT(ABS('LCIA (Annex 1)'!C21:C31))=0,0,('LCIA (Annex 1)'!C27)/SUMPRODUCT(ABS('LCIA (Annex 1)'!C21:C31))) -> 0.15558983 | D13: =IF(SUMPRODUCT(ABS('LCIA (Annex 1)'!C36:C46))=0,0,('LCIA (Annex 1)'!C42)/SUMPRODUCT(ABS('LCIA (Annex 1)'!C36:C46))) -> 0 | E13: =IF(SUMPRODUCT(ABS('LCIA (Annex 1)'!C51:C61))=0,0,('LCIA (Annex 1)'!C57)/SUMPRODUCT(ABS('LCIA (Annex 1)'!C51:C61))) -> 0.071428571 | F13: =IF(SUMPRODUCT(ABS('LCIA (Annex 1)'!C66:C76))=0,0,('LCIA (Annex 1)'!C72)/SUMPRODUCT(ABS('LCIA (Annex 1)'!C66:C76))) -> 0.038461538 | G13: =IF(SUMPRODUCT(ABS('LCIA (Annex 1)'!C81:C91))=0,0,('LCIA (Annex 1)'!C87)/SUMPRODUCT(ABS('LCIA (Annex 1)'!C81:C91))) -> 0.0020366599 | H13: =IF(SUMPRODUCT(ABS('LCIA (Annex 1)'!C96:C106))=0,0,('LCIA (Annex 1)'!C102)/SUMPRODUCT(ABS('LCIA (Annex 1)'!C96:C106))) -> 3.662087e-05
A14: Direct activity (farm area, water mgmt.) | B14: =IF(SUMPRODUCT(ABS('LCIA (Annex 1)'!C6:C16))=0,0,('LCIA (Annex 1)'!C16)/SUMPRODUCT(ABS('LCIA (Annex 1)'!C6:C16))) -> 0 | C14: =IF(SUMPRODUCT(ABS('LCIA (Annex 1)'!C21:C31))=0,0,('LCIA (Annex 1)'!C31)/SUMPRODUCT(ABS('LCIA (Annex 1)'!C21:C31))) -> 0 | D14: =IF(SUMPRODUCT(ABS('LCIA (Annex 1)'!C36:C46))=0,0,('LCIA (Annex 1)'!C46)/SUMPRODUCT(ABS('LCIA (Annex 1)'!C36:C46))) -> 0 | E14: =IF(SUMPRODUCT(ABS('LCIA (Annex 1)'!C51:C61))=0,0,('LCIA (Annex 1)'!C61)/SUMPRODUCT(ABS('LCIA (Annex 1)'!C51:C61))) -> 0 | F14: =IF(SUMPRODUCT(ABS('LCIA (Annex 1)'!C66:C76))=0,0,('LCIA (Annex 1)'!C76)/SUMPRODUCT(ABS('LCIA (Annex 1)'!C66:C76))) -> 0 | G14: =IF(SUMPRODUCT(ABS('LCIA (Annex 1)'!C81:C91))=0,0,('LCIA (Annex 1)'!C91)/SUMPRODUCT(ABS('LCIA (Annex 1)'!C81:C91))) -> 0.31941616 | H14: =IF(SUMPRODUCT(ABS('LCIA (Annex 1)'!C96:C106))=0,0,('LCIA (Annex 1)'!C106)/SUMPRODUCT(ABS('LCIA (Annex 1)'!C96:C106))) -> 0.49643252
A15: Water consumption | B15: =IF(SUMPRODUCT(ABS('LCIA (Annex 1)'!C6:C16))=0,0,('LCIA (Annex 1)'!C8)/SUMPRODUCT(ABS('LCIA (Annex 1)'!C6:C16))) -> 0 | C15: =IF(SUMPRODUCT(ABS('LCIA (Annex 1)'!C21:C31))=0,0,('LCIA (Annex 1)'!C23)/SUMPRODUCT(ABS('LCIA (Annex 1)'!C21:C31))) -> 0 | D15: =IF(SUMPRODUCT(ABS('LCIA (Annex 1)'!C36:C46))=0,0,('LCIA (Annex 1)'!C38)/SUMPRODUCT(ABS('LCIA (Annex 1)'!C36:C46))) -> 0 | E15: =IF(SUMPRODUCT(ABS('LCIA (Annex 1)'!C51:C61))=0,0,('LCIA (Annex 1)'!C53)/SUMPRODUCT(ABS('LCIA (Annex 1)'!C51:C61))) -> 0 | F15: =IF(SUMPRODUCT(ABS('LCIA (Annex 1)'!C66:C76))=0,0,('LCIA (Annex 1)'!C68)/SUMPRODUCT(ABS('LCIA (Annex 1)'!C66:C76))) -> 0 | G15: =IF(SUMPRODUCT(ABS('LCIA (Annex 1)'!C81:C91))=0,0,('LCIA (Annex 1)'!C83)/SUMPRODUCT(ABS('LCIA (Annex 1)'!C81:C91))) -> 0 | H15: =IF(SUMPRODUCT(ABS('LCIA (Annex 1)'!C96:C106))=0,0,('LCIA (Annex 1)'!C98)/SUMPRODUCT(ABS('LCIA (Annex 1)'!C96:C106))) -> 0.50207823
A16: Other (buildings, vehicles, chemicals, fry) | B16: =IF(SUMPRODUCT(ABS('LCIA (Annex 1)'!C6:C16))=0,0,('LCIA (Annex 1)'!C6+'LCIA (Annex 1)'!C9+'LCIA (Annex 1)'!C11+'LCIA (Annex 1)'!C13)/SUMPRODUCT(ABS('LCIA (Annex 1)'!C6:C16))) -> 0.075660243 | C16: =IF(SUMPRODUCT(ABS('LCIA (Annex 1)'!C21:C31))=0,0,('LCIA (Annex 1)'!C21+'LCIA (Annex 1)'!C24+'LCIA (Annex 1)'!C26+'LCIA (Annex 1)'!C28)/SUMPRODUCT(ABS('LCIA (Annex 1)'!C21:C31))) -> 0.042938931 | D16: =IF(SUMPRODUCT(ABS('LCIA (Annex 1)'!C36:C46))=0,0,('LCIA (Annex 1)'!C36+'LCIA (Annex 1)'!C39+'LCIA (Annex 1)'!C41+'LCIA (Annex 1)'!C43)/SUMPRODUCT(ABS('LCIA (Annex 1)'!C36:C46))) -> 0.0052490933 | E16: =IF(SUMPRODUCT(ABS('LCIA (Annex 1)'!C51:C61))=0,0,('LCIA (Annex 1)'!C51+'LCIA (Annex 1)'!C54+'LCIA (Annex 1)'!C56+'LCIA (Annex 1)'!C58)/SUMPRODUCT(ABS('LCIA (Annex 1)'!C51:C61))) -> 0.047619048 | F16: =IF(SUMPRODUCT(ABS('LCIA (Annex 1)'!C66:C76))=0,0,('LCIA (Annex 1)'!C66+'LCIA (Annex 1)'!C69+'LCIA (Annex 1)'!C71+'LCIA (Annex 1)'!C73)/SUMPRODUCT(ABS('LCIA (Annex 1)'!C66:C76))) -> 0 | G16: =IF(SUMPRODUCT(ABS('LCIA (Annex 1)'!C81:C91))=0,0,('LCIA (Annex 1)'!C81+'LCIA (Annex 1)'!C84+'LCIA (Annex 1)'!C86+'LCIA (Annex 1)'!C88)/SUMPRODUCT(ABS('LCIA (Annex 1)'!C81:C91))) -> 0.015274949 | H16: =IF(SUMPRODUCT(ABS('LCIA (Annex 1)'!C96:C106))=0,0,('LCIA (Annex 1)'!C96+'LCIA (Annex 1)'!C99+'LCIA (Annex 1)'!C101+'LCIA (Annex 1)'!C103)/SUMPRODUCT(ABS('LCIA (Annex 1)'!C96:C106))) -> 0.00091552176
A26: Semi-extensive pond IMTA
A27: Process group | B27: GW | C27: TCED | D27: NPPU | E27: AP | F27: EP | G27: LC | H27: WD
A28: Feeds | B28: =IF(SUMPRODUCT(ABS('LCIA (Annex 1)'!D6:D16))=0,0,('LCIA (Annex 1)'!D14)/SUMPRODUCT(ABS('LCIA (Annex 1)'!D6:D16))) -> 0.58452951 | C28: =IF(SUMPRODUCT(ABS('LCIA (Annex 1)'!D21:D31))=0,0,('LCIA (Annex 1)'!D29)/SUMPRODUCT(ABS('LCIA (Annex 1)'!D21:D31))) -> 0.41367754 | D28: =IF(SUMPRODUCT(ABS('LCIA (Annex 1)'!D36:D46))=0,0,('LCIA (Annex 1)'!D44)/SUMPRODUCT(ABS('LCIA (Annex 1)'!D36:D46))) -> 0.99159473 | E28: =IF(SUMPRODUCT(ABS('LCIA (Annex 1)'!D51:D61))=0,0,('LCIA (Annex 1)'!D59)/SUMPRODUCT(ABS('LCIA (Annex 1)'!D51:D61))) -> 0.6 | F28: =IF(SUMPRODUCT(ABS('LCIA (Annex 1)'!D66:D76))=0,0,('LCIA (Annex 1)'!D74)/SUMPRODUCT(ABS('LCIA (Annex 1)'!D66:D76))) -> 0.75 | G28: =IF(SUMPRODUCT(ABS('LCIA (Annex 1)'!D81:D91))=0,0,('LCIA (Annex 1)'!D89)/SUMPRODUCT(ABS('LCIA (Annex 1)'!D81:D91))) -> 0.13513514 | H28: =IF(SUMPRODUCT(ABS('LCIA (Annex 1)'!D96:D106))=0,0,('LCIA (Annex 1)'!D104)/SUMPRODUCT(ABS('LCIA (Annex 1)'!D96:D106))) -> 0.00012101096
A29: Rejects fish (uneaten feed, excretion) | B29: =IF(SUMPRODUCT(ABS('LCIA (Annex 1)'!D6:D16))=0,0,('LCIA (Annex 1)'!D10)/SUMPRODUCT(ABS('LCIA (Annex 1)'!D6:D16))) -> 0 | C29: =IF(SUMPRODUCT(ABS('LCIA (Annex 1)'!D21:D31))=0,0,('LCIA (Annex 1)'!D25)/SUMPRODUCT(ABS('LCIA (Annex 1)'!D21:D31))) -> 0 | D29: =IF(SUMPRODUCT(ABS('LCIA (Annex 1)'!D36:D46))=0,0,('LCIA (Annex 1)'!D40)/SUMPRODUCT(ABS('LCIA (Annex 1)'!D36:D46))) -> 0 | E29: =IF(SUMPRODUCT(ABS('LCIA (Annex 1)'!D51:D61))=0,0,('LCIA (Annex 1)'!D55)/SUMPRODUCT(ABS('LCIA (Annex 1)'!D51:D61))) -> 0 | F29: =IF(SUMPRODUCT(ABS('LCIA (Annex 1)'!D66:D76))=0,0,('LCIA (Annex 1)'!D70)/SUMPRODUCT(ABS('LCIA (Annex 1)'!D66:D76))) -> -0.25 | G29: =IF(SUMPRODUCT(ABS('LCIA (Annex 1)'!D81:D91))=0,0,('LCIA (Annex 1)'!D85)/SUMPRODUCT(ABS('LCIA (Annex 1)'!D81:D91))) -> 0 | H29: =IF(SUMPRODUCT(ABS('LCIA (Annex 1)'!D96:D106))=0,0,('LCIA (Annex 1)'!D100)/SUMPRODUCT(ABS('LCIA (Annex 1)'!D96:D106))) -> 0
A30: Energy consumption | B30: =IF(SUMPRODUCT(ABS('LCIA (Annex 1)'!D6:D16))=0,0,('LCIA (Annex 1)'!D7)/SUMPRODUCT(ABS('LCIA (Annex 1)'!D6:D16))) -> 0.004784689 | C30: =IF(SUMPRODUCT(ABS('LCIA (Annex 1)'!D21:D31))=0,0,('LCIA (Annex 1)'!D22)/SUMPRODUCT(ABS('LCIA (Annex 1)'!D21:D31))) -> 0.0042938681 | D30: =IF(SUMPRODUCT(ABS('LCIA (Annex 1)'!D36:D46))=0,0,('LCIA (Annex 1)'!D37)/SUMPRODUCT(ABS('LCIA (Annex 1)'!D36:D46))) -> 0 | E30: =IF(SUMPRODUCT(ABS('LCIA (Annex 1)'!D51:D61))=0,0,('LCIA (Annex 1)'!D52)/SUMPRODUCT(ABS('LCIA (Annex 1)'!D51:D61))) -> 0 | F30: =IF(SUMPRODUCT(ABS('LCIA (Annex 1)'!D66:D76))=0,0,('LCIA (Annex 1)'!D67)/SUMPRODUCT(ABS('LCIA (Annex 1)'!D66:D76))) -> 0 | G30: =IF(SUMPRODUCT(ABS('LCIA (Annex 1)'!D81:D91))=0,0,('LCIA (Annex 1)'!D82)/SUMPRODUCT(ABS('LCIA (Annex 1)'!D81:D91))) -> 0 | H30: =IF(SUMPRODUCT(ABS('LCIA (Annex 1)'!D96:D106))=0,0,('LCIA (Annex 1)'!D97)/SUMPRODUCT(ABS('LCIA (Annex 1)'!D96:D106))) -> 0
A31: Transports | B31: =IF(SUMPRODUCT(ABS('LCIA (Annex 1)'!D6:D16))=0,0,('LCIA (Annex 1)'!D15)/SUMPRODUCT(ABS('LCIA (Annex 1)'!D6:D16))) -> 0.16586922 | C31: =IF(SUMPRODUCT(ABS('LCIA (Annex 1)'!D21:D31))=0,0,('LCIA (Annex 1)'!D30)/SUMPRODUCT(ABS('LCIA (Annex 1)'!D21:D31))) -> 0.18311777 | D31: =IF(SUMPRODUCT(ABS('LCIA (Annex 1)'!D36:D46))=0,0,('LCIA (Annex 1)'!D45)/SUMPRODUCT(ABS('LCIA (Annex 1)'!D36:D46))) -> 0 | E31: =IF(SUMPRODUCT(ABS('LCIA (Annex 1)'!D51:D61))=0,0,('LCIA (Annex 1)'!D60)/SUMPRODUCT(ABS('LCIA (Annex 1)'!D51:D61))) -> 0.2 | F31: =IF(SUMPRODUCT(ABS('LCIA (Annex 1)'!D66:D76))=0,0,('LCIA (Annex 1)'!D75)/SUMPRODUCT(ABS('LCIA (Annex 1)'!D66:D76))) -> 0 | G31: =IF(SUMPRODUCT(ABS('LCIA (Annex 1)'!D81:D91))=0,0,('LCIA (Annex 1)'!D90)/SUMPRODUCT(ABS('LCIA (Annex 1)'!D81:D91))) -> 0.00061425061 | H31: =IF(SUMPRODUCT(ABS('LCIA (Annex 1)'!D96:D106))=0,0,('LCIA (Annex 1)'!D105)/SUMPRODUCT(ABS('LCIA (Annex 1)'!D96:D106))) -> 1.728728e-05
A32: Equipment | B32: =IF(SUMPRODUCT(ABS('LCIA (Annex 1)'!D6:D16))=0,0,('LCIA (Annex 1)'!D12)/SUMPRODUCT(ABS('LCIA (Annex 1)'!D6:D16))) -> 0.18181818 | C32: =IF(SUMPRODUCT(ABS('LCIA (Annex 1)'!D21:D31))=0,0,('LCIA (Annex 1)'!D27)/SUMPRODUCT(ABS('LCIA (Annex 1)'!D21:D31))) -> 0.32717181 | D32: =IF(SUMPRODUCT(ABS('LCIA (Annex 1)'!D36:D46))=0,0,('LCIA (Annex 1)'!D42)/SUMPRODUCT(ABS('LCIA (Annex 1)'!D36:D46))) -> 0 | E32: =IF(SUMPRODUCT(ABS('LCIA (Annex 1)'!D51:D61))=0,0,('LCIA (Annex 1)'!D57)/SUMPRODUCT(ABS('LCIA (Annex 1)'!D51:D61))) -> 0.2 | F32: =IF(SUMPRODUCT(ABS('LCIA (Annex 1)'!D66:D76))=0,0,('LCIA (Annex 1)'!D72)/SUMPRODUCT(ABS('LCIA (Annex 1)'!D66:D76))) -> 0 | G32: =IF(SUMPRODUCT(ABS('LCIA (Annex 1)'!D81:D91))=0,0,('LCIA (Annex 1)'!D87)/SUMPRODUCT(ABS('LCIA (Annex 1)'!D81:D91))) -> 0 | H32: =IF(SUMPRODUCT(ABS('LCIA (Annex 1)'!D96:D106))=0,0,('LCIA (Annex 1)'!D102)/SUMPRODUCT(ABS('LCIA (Annex 1)'!D96:D106))) -> 4.32182e-05
A33: Direct activity (farm area, water mgmt.) | B33: =IF(SUMPRODUCT(ABS('LCIA (Annex 1)'!D6:D16))=0,0,('LCIA (Annex 1)'!D16)/SUMPRODUCT(ABS('LCIA (Annex 1)'!D6:D16))) -> 0 | C33: =IF(SUMPRODUCT(ABS('LCIA (Annex 1)'!D21:D31))=0,0,('LCIA (Annex 1)'!D31)/SUMPRODUCT(ABS('LCIA (Annex 1)'!D21:D31))) -> 0 | D33: =IF(SUMPRODUCT(ABS('LCIA (Annex 1)'!D36:D46))=0,0,('LCIA (Annex 1)'!D46)/SUMPRODUCT(ABS('LCIA (Annex 1)'!D36:D46))) -> 0 | E33: =IF(SUMPRODUCT(ABS('LCIA (Annex 1)'!D51:D61))=0,0,('LCIA (Annex 1)'!D61)/SUMPRODUCT(ABS('LCIA (Annex 1)'!D51:D61))) -> 0 | F33: =IF(SUMPRODUCT(ABS('LCIA (Annex 1)'!D66:D76))=0,0,('LCIA (Annex 1)'!D76)/SUMPRODUCT(ABS('LCIA (Annex 1)'!D66:D76))) -> 0 | G33: =IF(SUMPRODUCT(ABS('LCIA (Annex 1)'!D81:D91))=0,0,('LCIA (Annex 1)'!D91)/SUMPRODUCT(ABS('LCIA (Annex 1)'!D81:D91))) -> 0.85872236 | H33: =IF(SUMPRODUCT(ABS('LCIA (Annex 1)'!D96:D106))=0,0,('LCIA (Annex 1)'!D106)/SUMPRODUCT(ABS('LCIA (Annex 1)'!D96:D106))) -> 0.60762196
A34: Water consumption | B34: =IF(SUMPRODUCT(ABS('LCIA (Annex 1)'!D6:D16))=0,0,('LCIA (Annex 1)'!D8)/SUMPRODUCT(ABS('LCIA (Annex 1)'!D6:D16))) -> 0 | C34: =IF(SUMPRODUCT(ABS('LCIA (Annex 1)'!D21:D31))=0,0,('LCIA (Annex 1)'!D23)/SUMPRODUCT(ABS('LCIA (Annex 1)'!D21:D31))) -> 0 | D34: =IF(SUMPRODUCT(ABS('LCIA (Annex 1)'!D36:D46))=0,0,('LCIA (Annex 1)'!D38)/SUMPRODUCT(ABS('LCIA (Annex 1)'!D36:D46))) -> 0 | E34: =IF(SUMPRODUCT(ABS('LCIA (Annex 1)'!D51:D61))=0,0,('LCIA (Annex 1)'!D53)/SUMPRODUCT(ABS('LCIA (Annex 1)'!D51:D61))) -> 0 | F34: =IF(SUMPRODUCT(ABS('LCIA (Annex 1)'!D66:D76))=0,0,('LCIA (Annex 1)'!D68)/SUMPRODUCT(ABS('LCIA (Annex 1)'!D66:D76))) -> 0 | G34: =IF(SUMPRODUCT(ABS('LCIA (Annex 1)'!D81:D91))=0,0,('LCIA (Annex 1)'!D83)/SUMPRODUCT(ABS('LCIA (Annex 1)'!D81:D91))) -> 0 | H34: =IF(SUMPRODUCT(ABS('LCIA (Annex 1)'!D96:D106))=0,0,('LCIA (Annex 1)'!D98)/SUMPRODUCT(ABS('LCIA (Annex 1)'!D96:D106))) -> 0.39132351
A35: Other (buildings, vehicles, chemicals, fry) | B35: =IF(SUMPRODUCT(ABS('LCIA (Annex 1)'!D6:D16))=0,0,('LCIA (Annex 1)'!D6+'LCIA (Annex 1)'!D9+'LCIA (Annex 1)'!D11+'LCIA (Annex 1)'!D13)/SUMPRODUCT(ABS('LCIA (Annex 1)'!D6:D16))) -> 0.062998405 | C35: =IF(SUMPRODUCT(ABS('LCIA (Annex 1)'!D21:D31))=0,0,('LCIA (Annex 1)'!D21+'LCIA (Annex 1)'!D24+'LCIA (Annex 1)'!D26+'LCIA (Annex 1)'!D28)/SUMPRODUCT(ABS('LCIA (Annex 1)'!D21:D31))) -> 0.071739017 | D35: =IF(SUMPRODUCT(ABS('LCIA (Annex 1)'!D36:D46))=0,0,('LCIA (Annex 1)'!D36+'LCIA (Annex 1)'!D39+'LCIA (Annex 1)'!D41+'LCIA (Annex 1)'!D43)/SUMPRODUCT(ABS('LCIA (Annex 1)'!D36:D46))) -> 0.0084052703 | E35: =IF(SUMPRODUCT(ABS('LCIA (Annex 1)'!D51:D61))=0,0,('LCIA (Annex 1)'!D51+'LCIA (Annex 1)'!D54+'LCIA (Annex 1)'!D56+'LCIA (Annex 1)'!D58)/SUMPRODUCT(ABS('LCIA (Annex 1)'!D51:D61))) -> 0 | F35: =IF(SUMPRODUCT(ABS('LCIA (Annex 1)'!D66:D76))=0,0,('LCIA (Annex 1)'!D66+'LCIA (Annex 1)'!D69+'LCIA (Annex 1)'!D71+'LCIA (Annex 1)'!D73)/SUMPRODUCT(ABS('LCIA (Annex 1)'!D66:D76))) -> 0 | G35: =IF(SUMPRODUCT(ABS('LCIA (Annex 1)'!D81:D91))=0,0,('LCIA (Annex 1)'!D81+'LCIA (Annex 1)'!D84+'LCIA (Annex 1)'!D86+'LCIA (Annex 1)'!D88)/SUMPRODUCT(ABS('LCIA (Annex 1)'!D81:D91))) -> 0.0055282555 | H35: =IF(SUMPRODUCT(ABS('LCIA (Annex 1)'!D96:D106))=0,0,('LCIA (Annex 1)'!D96+'LCIA (Annex 1)'!D99+'LCIA (Annex 1)'!D101+'LCIA (Annex 1)'!D103)/SUMPRODUCT(ABS('LCIA (Annex 1)'!D96:D106))) -> 0.00087300764
A45: Semi-intensive fish polyculture
A46: Process group | B46: GW | C46: TCED | D46: NPPU | E46: AP | F46: EP | G46: LC | H46: WD
A47: Feeds | B47: =IF(SUMPRODUCT(ABS('LCIA (Annex 1)'!E6:E16))=0,0,('LCIA (Annex 1)'!E14)/SUMPRODUCT(ABS('LCIA (Annex 1)'!E6:E16))) -> 0.66067019 | C47: =IF(SUMPRODUCT(ABS('LCIA (Annex 1)'!E21:E31))=0,0,('LCIA (Annex 1)'!E29)/SUMPRODUCT(ABS('LCIA (Annex 1)'!E21:E31))) -> 0.25210967 | D47: =IF(SUMPRODUCT(ABS('LCIA (Annex 1)'!E36:E46))=0,0,('LCIA (Annex 1)'!E44)/SUMPRODUCT(ABS('LCIA (Annex 1)'!E36:E46))) -> 0.99991908 | E47: =IF(SUMPRODUCT(ABS('LCIA (Annex 1)'!E51:E61))=0,0,('LCIA (Annex 1)'!E59)/SUMPRODUCT(ABS('LCIA (Annex 1)'!E51:E61))) -> 0.22727273 | F47: =IF(SUMPRODUCT(ABS('LCIA (Annex 1)'!E66:E76))=0,0,('LCIA (Annex 1)'!E74)/SUMPRODUCT(ABS('LCIA (Annex 1)'!E66:E76))) -> 0.13333333 | G47: =IF(SUMPRODUCT(ABS('LCIA (Annex 1)'!E81:E91))=0,0,('LCIA (Annex 1)'!E89)/SUMPRODUCT(ABS('LCIA (Annex 1)'!E81:E91))) -> 0.79806479 | H47: =IF(SUMPRODUCT(ABS('LCIA (Annex 1)'!E96:E106))=0,0,('LCIA (Annex 1)'!E104)/SUMPRODUCT(ABS('LCIA (Annex 1)'!E96:E106))) -> 0.00011195872
A48: Rejects fish (uneaten feed, excretion) | B48: =IF(SUMPRODUCT(ABS('LCIA (Annex 1)'!E6:E16))=0,0,('LCIA (Annex 1)'!E10)/SUMPRODUCT(ABS('LCIA (Annex 1)'!E6:E16))) -> 0 | C48: =IF(SUMPRODUCT(ABS('LCIA (Annex 1)'!E21:E31))=0,0,('LCIA (Annex 1)'!E25)/SUMPRODUCT(ABS('LCIA (Annex 1)'!E21:E31))) -> 0 | D48: =IF(SUMPRODUCT(ABS('LCIA (Annex 1)'!E36:E46))=0,0,('LCIA (Annex 1)'!E40)/SUMPRODUCT(ABS('LCIA (Annex 1)'!E36:E46))) -> 0 | E48: =IF(SUMPRODUCT(ABS('LCIA (Annex 1)'!E51:E61))=0,0,('LCIA (Annex 1)'!E55)/SUMPRODUCT(ABS('LCIA (Annex 1)'!E51:E61))) -> 0.65909091 | F48: =IF(SUMPRODUCT(ABS('LCIA (Annex 1)'!E66:E76))=0,0,('LCIA (Annex 1)'!E70)/SUMPRODUCT(ABS('LCIA (Annex 1)'!E66:E76))) -> 0.85 | G48: =IF(SUMPRODUCT(ABS('LCIA (Annex 1)'!E81:E91))=0,0,('LCIA (Annex 1)'!E85)/SUMPRODUCT(ABS('LCIA (Annex 1)'!E81:E91))) -> 0 | H48: =IF(SUMPRODUCT(ABS('LCIA (Annex 1)'!E96:E106))=0,0,('LCIA (Annex 1)'!E100)/SUMPRODUCT(ABS('LCIA (Annex 1)'!E96:E106))) -> 0
A49: Energy consumption | B49: =IF(SUMPRODUCT(ABS('LCIA (Annex 1)'!E6:E16))=0,0,('LCIA (Annex 1)'!E7)/SUMPRODUCT(ABS('LCIA (Annex 1)'!E6:E16))) -> 0.16719577 | C49: =IF(SUMPRODUCT(ABS('LCIA (Annex 1)'!E21:E31))=0,0,('LCIA (Annex 1)'!E22)/SUMPRODUCT(ABS('LCIA (Annex 1)'!E21:E31))) -> 0.65791766 | D49: =IF(SUMPRODUCT(ABS('LCIA (Annex 1)'!E36:E46))=0,0,('LCIA (Annex 1)'!E37)/SUMPRODUCT(ABS('LCIA (Annex 1)'!E36:E46))) -> 0 | E49: =IF(SUMPRODUCT(ABS('LCIA (Annex 1)'!E51:E61))=0,0,('LCIA (Annex 1)'!E52)/SUMPRODUCT(ABS('LCIA (Annex 1)'!E51:E61))) -> 0.068181818 | F49: =IF(SUMPRODUCT(ABS('LCIA (Annex 1)'!E66:E76))=0,0,('LCIA (Annex 1)'!E67)/SUMPRODUCT(ABS('LCIA (Annex 1)'!E66:E76))) -> 0.016666667 | G49: =IF(SUMPRODUCT(ABS('LCIA (Annex 1)'!E81:E91))=0,0,('LCIA (Annex 1)'!E82)/SUMPRODUCT(ABS('LCIA (Annex 1)'!E81:E91))) -> 0.0050483803 | H49: =IF(SUMPRODUCT(ABS('LCIA (Annex 1)'!E96:E106))=0,0,('LCIA (Annex 1)'!E97)/SUMPRODUCT(ABS('LCIA (Annex 1)'!E96:E106))) -> 0.00013740388
A50: Transports | B50: =IF(SUMPRODUCT(ABS('LCIA (Annex 1)'!E6:E16))=0,0,('LCIA (Annex 1)'!E15)/SUMPRODUCT(ABS('LCIA (Annex 1)'!E6:E16))) -> 0.13368607 | C50: =IF(SUMPRODUCT(ABS('LCIA (Annex 1)'!E21:E31))=0,0,('LCIA (Annex 1)'!E30)/SUMPRODUCT(ABS('LCIA (Annex 1)'!E21:E31))) -> 0.064156081 | D50: =IF(SUMPRODUCT(ABS('LCIA (Annex 1)'!E36:E46))=0,0,('LCIA (Annex 1)'!E45)/SUMPRODUCT(ABS('LCIA (Annex 1)'!E36:E46))) -> 0 | E50: =IF(SUMPRODUCT(ABS('LCIA (Annex 1)'!E51:E61))=0,0,('LCIA (Annex 1)'!E60)/SUMPRODUCT(ABS('LCIA (Annex 1)'!E51:E61))) -> 0.045454545 | F50: =IF(SUMPRODUCT(ABS('LCIA (Annex 1)'!E66:E76))=0,0,('LCIA (Annex 1)'!E75)/SUMPRODUCT(ABS('LCIA (Annex 1)'!E66:E76))) -> 0 | G50: =IF(SUMPRODUCT(ABS('LCIA (Annex 1)'!E81:E91))=0,0,('LCIA (Annex 1)'!E90)/SUMPRODUCT(ABS('LCIA (Annex 1)'!E81:E91))) -> 0.0021034918 | H50: =IF(SUMPRODUCT(ABS('LCIA (Annex 1)'!E96:E106))=0,0,('LCIA (Annex 1)'!E105)/SUMPRODUCT(ABS('LCIA (Annex 1)'!E96:E106))) -> 7.6335489e-06
A51: Equipment | B51: =IF(SUMPRODUCT(ABS('LCIA (Annex 1)'!E6:E16))=0,0,('LCIA (Annex 1)'!E12)/SUMPRODUCT(ABS('LCIA (Annex 1)'!E6:E16))) -> 0.0052910053 | C51: =IF(SUMPRODUCT(ABS('LCIA (Annex 1)'!E21:E31))=0,0,('LCIA (Annex 1)'!E27)/SUMPRODUCT(ABS('LCIA (Annex 1)'!E21:E31))) -> 0.0055557224 | D51: =IF(SUMPRODUCT(ABS('LCIA (Annex 1)'!E36:E46))=0,0,('LCIA (Annex 1)'!E42)/SUMPRODUCT(ABS('LCIA (Annex 1)'!E36:E46))) -> 0 | E51: =IF(SUMPRODUCT(ABS('LCIA (Annex 1)'!E51:E61))=0,0,('LCIA (Annex 1)'!E57)/SUMPRODUCT(ABS('LCIA (Annex 1)'!E51:E61))) -> 0 | F51: =IF(SUMPRODUCT(ABS('LCIA (Annex 1)'!E66:E76))=0,0,('LCIA (Annex 1)'!E72)/SUMPRODUCT(ABS('LCIA (Annex 1)'!E66:E76))) -> 0 | G51: =IF(SUMPRODUCT(ABS('LCIA (Annex 1)'!E81:E91))=0,0,('LCIA (Annex 1)'!E87)/SUMPRODUCT(ABS('LCIA (Annex 1)'!E81:E91))) -> 0 | H51: =IF(SUMPRODUCT(ABS('LCIA (Annex 1)'!E96:E106))=0,0,('LCIA (Annex 1)'!E102)/SUMPRODUCT(ABS('LCIA (Annex 1)'!E96:E106))) -> 0
A52: Direct activity (farm area, water mgmt.) | B52: =IF(SUMPRODUCT(ABS('LCIA (Annex 1)'!E6:E16))=0,0,('LCIA (Annex 1)'!E16)/SUMPRODUCT(ABS('LCIA (Annex 1)'!E6:E16))) -> 0 | C52: =IF(SUMPRODUCT(ABS('LCIA (Annex 1)'!E21:E31))=0,0,('LCIA (Annex 1)'!E31)/SUMPRODUCT(ABS('LCIA (Annex 1)'!E21:E31))) -> 0 | D52: =IF(SUMPRODUCT(ABS('LCIA (Annex 1)'!E36:E46))=0,0,('LCIA (Annex 1)'!E46)/SUMPRODUCT(ABS('LCIA (Annex 1)'!E36:E46))) -> 0 | E52: =IF(SUMPRODUCT(ABS('LCIA (Annex 1)'!E51:E61))=0,0,('LCIA (Annex 1)'!E61)/SUMPRODUCT(ABS('LCIA (Annex 1)'!E51:E61))) -> 0 | F52: =IF(SUMPRODUCT(ABS('LCIA (Annex 1)'!E66:E76))=0,0,('LCIA (Annex 1)'!E76)/SUMPRODUCT(ABS('LCIA (Annex 1)'!E66:E76))) -> 0 | G52: =IF(SUMPRODUCT(ABS('LCIA (Annex 1)'!E81:E91))=0,0,('LCIA (Annex 1)'!E91)/SUMPRODUCT(ABS('LCIA (Annex 1)'!E81:E91))) -> 0.19352125 | H52: =IF(SUMPRODUCT(ABS('LCIA (Annex 1)'!E96:E106))=0,0,('LCIA (Annex 1)'!E106)/SUMPRODUCT(ABS('LCIA (Annex 1)'!E96:E106))) -> 0.5014402
A53: Water consumption | B53: =IF(SUMPRODUCT(ABS('LCIA (Annex 1)'!E6:E16))=0,0,('LCIA (Annex 1)'!E8)/SUMPRODUCT(ABS('LCIA (Annex 1)'!E6:E16))) -> 0 | C53: =IF(SUMPRODUCT(ABS('LCIA (Annex 1)'!E21:E31))=0,0,('LCIA (Annex 1)'!E23)/SUMPRODUCT(ABS('LCIA (Annex 1)'!E21:E31))) -> 0 | D53: =IF(SUMPRODUCT(ABS('LCIA (Annex 1)'!E36:E46))=0,0,('LCIA (Annex 1)'!E38)/SUMPRODUCT(ABS('LCIA (Annex 1)'!E36:E46))) -> 0 | E53: =IF(SUMPRODUCT(ABS('LCIA (Annex 1)'!E51:E61))=0,0,('LCIA (Annex 1)'!E53)/SUMPRODUCT(ABS('LCIA (Annex 1)'!E51:E61))) -> 0 | F53: =IF(SUMPRODUCT(ABS('LCIA (Annex 1)'!E66:E76))=0,0,('LCIA (Annex 1)'!E68)/SUMPRODUCT(ABS('LCIA (Annex 1)'!E66:E76))) -> 0 | G53: =IF(SUMPRODUCT(ABS('LCIA (Annex 1)'!E81:E91))=0,0,('LCIA (Annex 1)'!E83)/SUMPRODUCT(ABS('LCIA (Annex 1)'!E81:E91))) -> 0 | H53: =IF(SUMPRODUCT(ABS('LCIA (Annex 1)'!E96:E106))=0,0,('LCIA (Annex 1)'!E98)/SUMPRODUCT(ABS('LCIA (Annex 1)'!E96:E106))) -> 0.49829009
A54: Other (buildings, vehicles, chemicals, fry) | B54: =IF(SUMPRODUCT(ABS('LCIA (Annex 1)'!E6:E16))=0,0,('LCIA (Annex 1)'!E6+'LCIA (Annex 1)'!E9+'LCIA (Annex 1)'!E11+'LCIA (Annex 1)'!E13)/SUMPRODUCT(ABS('LCIA (Annex 1)'!E6:E16))) -> 0.033156966 | C54: =IF(SUMPRODUCT(ABS('LCIA (Annex 1)'!E21:E31))=0,0,('LCIA (Annex 1)'!E21+'LCIA (Annex 1)'!E24+'LCIA (Annex 1)'!E26+'LCIA (Annex 1)'!E28)/SUMPRODUCT(ABS('LCIA (Annex 1)'!E21:E31))) -> 0.020260869 | D54: =IF(SUMPRODUCT(ABS('LCIA (Annex 1)'!E36:E46))=0,0,('LCIA (Annex 1)'!E36+'LCIA (Annex 1)'!E39+'LCIA (Annex 1)'!E41+'LCIA (Annex 1)'!E43)/SUMPRODUCT(ABS('LCIA (Annex 1)'!E36:E46))) -> 8.0919243e-05 | E54: =IF(SUMPRODUCT(ABS('LCIA (Annex 1)'!E51:E61))=0,0,('LCIA (Annex 1)'!E51+'LCIA (Annex 1)'!E54+'LCIA (Annex 1)'!E56+'LCIA (Annex 1)'!E58)/SUMPRODUCT(ABS('LCIA (Annex 1)'!E51:E61))) -> 0 | F54: =IF(SUMPRODUCT(ABS('LCIA (Annex 1)'!E66:E76))=0,0,('LCIA (Annex 1)'!E66+'LCIA (Annex 1)'!E69+'LCIA (Annex 1)'!E71+'LCIA (Annex 1)'!E73)/SUMPRODUCT(ABS('LCIA (Annex 1)'!E66:E76))) -> 0 | G54: =IF(SUMPRODUCT(ABS('LCIA (Annex 1)'!E81:E91))=0,0,('LCIA (Annex 1)'!E81+'LCIA (Annex 1)'!E84+'LCIA (Annex 1)'!E86+'LCIA (Annex 1)'!E88)/SUMPRODUCT(ABS('LCIA (Annex 1)'!E81:E91))) -> 0.0012620951 | H54: =IF(SUMPRODUCT(ABS('LCIA (Annex 1)'!E96:E106))=0,0,('LCIA (Annex 1)'!E96+'LCIA (Annex 1)'!E99+'LCIA (Annex 1)'!E101+'LCIA (Annex 1)'!E103)/SUMPRODUCT(ABS('LCIA (Annex 1)'!E96:E106))) -> 1.2722582e-05
A64: 2 Contribution per impact category, absolute amounts per tonne (stacked by process group)
A66: GW - Global warming (kg CO2-eq per t)
A67: Process group | C67: Semi-intensive pond IMTA | D67: Semi-extensive pond IMTA | E67: Semi-intensive fish polyculture
A68: Feeds | C68: ='LCIA (Annex 1)'!C14 -> 1549 | D68: ='LCIA (Annex 1)'!D14 -> 733 | E68: ='LCIA (Annex 1)'!E14 -> 1873
A69: Rejects fish (uneaten feed, excretion) | C69: ='LCIA (Annex 1)'!C10 -> 0 | D69: ='LCIA (Annex 1)'!D10 -> 0 | E69: ='LCIA (Annex 1)'!E10 -> 0
A70: Energy consumption | C70: ='LCIA (Annex 1)'!C7 -> 330 | D70: ='LCIA (Annex 1)'!D7 -> 6 | E70: ='LCIA (Annex 1)'!E7 -> 474
...

Sheet Comparison
A1: Comparison per tonne of fish + oyster, and change against the polyculture baseline
A2: Source: INTEGRATE deliverable PI05#3 (IPMA & CTAQUA, 2020)
A4: Impact category | B4: Unit | C4: Semi-intensive pond IMTA | D4: Semi-extensive pond IMTA | E4: Semi-intensive fish polyculture | F4: SI-IMTA vs POLY | G4: SE-IMTA vs POLY | H4: Lowest
A5: GW - Global warming | B5: kg CO2-eq | C5: ='LCIA (Annex 1)'!C18 -> 2801 | D5: ='LCIA (Annex 1)'!D18 -> 1255 | E5: ='LCIA (Annex 1)'!E18 -> 2836 | F5: =C5/E5-1 -> -0.012341326 | G5: =D5/E5-1 -> -0.55747532 | H5: =INDEX($C$4:$E$4,MATCH(MIN(C5:E5),C5:E5,0)) -> Semi-extensive pond IMTA
A6: TCED - Cumulative energy demand | B6: MJ-eq | C6: ='LCIA (Annex 1)'!C33 -> 90127 | D6: ='LCIA (Annex 1)'!D33 -> 19097 | E6: ='LCIA (Annex 1)'!E33 -> 99897 | F6: =C6/E6-1 -> -0.097800735 | G6: =D6/E6-1 -> -0.8088331 | H6: =INDEX($C$4:$E$4,MATCH(MIN(C6:E6),C6:E6,0)) -> Semi-extensive pond IMTA
A7: NPPU - Net primary production use | B7: kg C | C7: ='LCIA (Annex 1)'!C48 -> 10478 | D7: ='LCIA (Annex 1)'!D48 -> 4402 | E7: ='LCIA (Annex 1)'!E48 -> 12358 | F7: =C7/E7-1 -> -0.15212818 | G7: =D7/E7-1 -> -0.64379349 | H7: =INDEX($C$4:$E$4,MATCH(MIN(C7:E7),C7:E7,0)) -> Semi-extensive pond IMTA
A8: AP - Acidification | B8: kg SO2-eq | C8: ='LCIA (Annex 1)'!C63 -> 42 | D8: ='LCIA (Annex 1)'!D63 -> 6 | E8: ='LCIA (Annex 1)'!E63 -> 45 | F8: =C8/E8-1 -> -0.066666667 | G8: =D8/E8-1 -> -0.86666667 | H8: =INDEX($C$4:$E$4,MATCH(MIN(C8:E8),C8:E8,0)) -> Semi-extensive pond IMTA
A9: EP - Eutrophication | B9: kg PO4-eq | C9: ='LCIA (Annex 1)'!C78 -> 26 | D9: ='LCIA (Annex 1)'!D78 -> 2 | E9: ='LCIA (Annex 1)'!E78 -> 61 | F9: =C9/E9-1 -> -0.57377049 | G9: =D9/E9-1 -> -0.96721311 | H9: =INDEX($C$4:$E$4,MATCH(MIN(C9:E9),C9:E9,0)) -> Semi-extensive pond IMTA
A10: LC - Land competition | B10: m2a | C10: ='LCIA (Annex 1)'!C93 -> 2946 | D10: ='LCIA (Annex 1)'!D93 -> 4885 | E10: ='LCIA (Annex 1)'!E93 -> 2379 | F10: =C10/E10-1 -> 0.23833544 | G10: =D10/E10-1 -> 1.0533838 | H10: =INDEX($C$4:$E$4,MATCH(MIN(C10:E10),C10:E10,0)) -> Semi-intensive fish polyculture
A11: WD - Water dependence | B11: m3 | C11: ='LCIA (Annex 1)'!C108 -> 163840 | D11: ='LCIA (Annex 1)'!D108 -> 115691 | E11: ='LCIA (Annex 1)'!E108 -> 393002 | F11: =C11/E11-1 -> -0.58310645 | G11: =D11/E11-1 -> -0.70562236 | H11: =INDEX($C$4:$E$4,MATCH(MIN(C11:E11),C11:E11,0)) -> Semi-extensive pond IMTA
A14: Implied impact per kg of feed (Feeds process / feed per tonne) - a check that the feed model is consistent
A15: Indicator | B15: Unit | C15: Semi-intensive pond IMTA | D15: Semi-extensive pond IMTA | E15: Semi-intensive fish polyculture
A16: Global warming of feed | B16: kg CO2-eq/kg feed | C16: ='LCIA (Annex 1)'!C14/'LCI per tonne'!C8 -> 1.0083268 | D16: ='LCIA (Annex 1)'!D14/'LCI per tonne'!D8 -> 1.3095169 | E16: ='LCIA (Annex 1)'!E14/'LCI per tonne'!E8 -> 1.0473441
A17: Cumulative energy demand of feed | B17: MJ-eq/kg feed | C17: ='LCIA (Annex 1)'!C29/'LCI per tonne'!C8 -> 13.688248 | D17: ='LCIA (Annex 1)'!D29/'LCI per tonne'!D8 -> 14.113483 | E17: ='LCIA (Annex 1)'!E29/'LCI per tonne'!E8 -> 14.082947
A18: Net primary production use of feed | B18: kg C/kg feed | C18: ='LCIA (Annex 1)'!C44/'LCI per tonne'!C8 -> 6.7848872 | D18: ='LCIA (Annex 1)'!D44/'LCI per tonne'!D8 -> 7.7981461 | E18: ='LCIA (Annex 1)'!E44/'LCI per tonne'!E8 -> 6.9097867

Sheet KPI framework
A1: KPI framework - 13 KPIs per tonne of fish + oyster
A2: Source: INTEGRATE deliverable PI05#3 (IPMA & CTAQUA, 2020)
A5: Improvement target for environmental KPIs (better than polyculture by at least): | F5: 0.1 | G5: E-targets = polyculture value x (1 - this). Circularity targets are set per KPI (yellow).
A7: ID | B7: Dimension | C7: KPI | D7: Unit | E7: Better if | F7: Target | G7: Value SI-IMTA | H7: Value SE-IMTA | I7: Value SI-POLY | J7: Met SI-IMTA | K7: Met SE-IMTA | L7: Met SI-POLY | M7: Formula
A8: E1 | B8: Environment | C8: Global warming | D8: kg CO2-eq/t | E8: lower | F8: ='LCIA (Annex 1)'!E18*(1-$F$5) -> 2552.4 | G8: ='LCIA (Annex 1)'!C18 -> 2801 | H8: ='LCIA (Annex 1)'!D18 -> 1255 | I8: ='LCIA (Annex 1)'!E18 -> 2836 | J8: =IF(G8<=$F8,"✓","✗") -> ✗ | K8: =IF(H8<=$F8,"✓","✗") -> ✓ | L8: baseline | M8: Annex 1 total; target = polyculture x (1 - improvement)
A9: E2 | B9: Environment | C9: Cumulative energy demand | D9: MJ-eq/t | E9: lower | F9: ='LCIA (Annex 1)'!E33*(1-$F$5) -> 89907.3 | G9: ='LCIA (Annex 1)'!C33 -> 90127 | H9: ='LCIA (Annex 1)'!D33 -> 19097 | I9: ='LCIA (Annex 1)'!E33 -> 99897 | J9: =IF(G9<=$F9,"✓","✗") -> ✗ | K9: =IF(H9<=$F9,"✓","✗") -> ✓ | L9: baseline | M9: Annex 1 total; target = polyculture x (1 - improvement)
A10: E3 | B10: Environment | C10: Net primary production use | D10: kg C/t | E10: lower | F10: ='LCIA (Annex 1)'!E48*(1-$F$5) -> 11122.2 | G10: ='LCIA (Annex 1)'!C48 -> 10478 | H10: ='LCIA (Annex 1)'!D48 -> 4402 | I10: ='LCIA (Annex 1)'!E48 -> 12358 | J10: =IF(G10<=$F10,"✓","✗") -> ✓ | K10: =IF(H10<=$F10,"✓","✗") -> ✓ | L10: baseline | M10: Annex 1 total; target = polyculture x (1 - improvement)
A11: E4 | B11: Environment | C11: Acidification | D11: kg SO2-eq/t | E11: lower | F11: ='LCIA (Annex 1)'!E63*(1-$F$5) -> 40.5 | G11: ='LCIA (Annex 1)'!C63 -> 42 | H11: ='LCIA (Annex 1)'!D63 -> 6 | I11: ='LCIA (Annex 1)'!E63 -> 45 | J11: =IF(G11<=$F11,"✓","✗") -> ✗ | K11: =IF(H11<=$F11,"✓","✗") -> ✓ | L11: baseline | M11: Annex 1 total; target = polyculture x (1 - improvement)
A12: E5 | B12: Environment | C12: Eutrophication | D12: kg PO4-eq/t | E12: lower | F12: ='LCIA (Annex 1)'!E78*(1-$F$5) -> 54.9 | G12: ='LCIA (Annex 1)'!C78 -> 26 | H12: ='LCIA (Annex 1)'!D78 -> 2 | I12: ='LCIA (Annex 1)'!E78 -> 61 | J12: =IF(G12<=$F12,"✓","✗") -> ✓ | K12: =IF(H12<=$F12,"✓","✗") -> ✓ | L12: baseline | M12: Annex 1 total; target = polyculture x (1 - improvement)
A13: E6 | B13: Environment | C13: Land competition | D13: m2a/t | E13: lower | F13: ='LCIA (Annex 1)'!E93*(1-$F$5) -> 2141.1 | G13: ='LCIA (Annex 1)'!C93 -> 2946 | H13: ='LCIA (Annex 1)'!D93 -> 4885 | I13: ='LCIA (Annex 1)'!E93 -> 2379 | J13: =IF(G13<=$F13,"✓","✗") -> ✗ | K13: =IF(H13<=$F13,"✓","✗") -> ✗ | L13: baseline | M13: Annex 1 total; target = polyculture x (1 - improvement)
A14: E7 | B14: Environment | C14: Water dependence | D14: m3/t | E14: lower | F14: ='LCIA (Annex 1)'!E108*(1-$F$5) -> 353701.8 | G14: ='LCIA (Annex 1)'!C108 -> 163840 | H14: ='LCIA (Annex 1)'!D108 -> 115691 | I14: ='LCIA (Annex 1)'!E108 -> 393002 | J14: =IF(G14<=$F14,"✓","✗") -> ✓ | K14: =IF(H14<=$F14,"✓","✗") -> ✓ | L14: baseline | M14: Annex 1 total; target = polyculture x (1 - improvement)
A15: C1 | B15: Circularity | C15: Nitrogen use efficiency | D15: % | E15: higher | F15: 0.35 | G15: ='Nutrient balance'!C13 -> 0.46975888 | H15: ='Nutrient balance'!D13 -> 1.1060393 | I15: ='Nutrient balance'!E13 -> 0.20175724 | J15: =IF(G15>=$F15,"✓","✗") -> ✓ | K15: =IF(H15>=$F15,"✓","✗") -> ✓ | L15: =IF(I15>=$F15,"✓","✗") -> ✗ | M15: (N in fish + oysters + macroalgae) / N in feed
A16: C2 | B16: Circularity | C16: Phosphorus use efficiency | D16: % | E16: higher | F16: 0.3 | G16: ='Nutrient balance'!C22 -> 0.3215799 | H16: ='Nutrient balance'!D22 -> 0.95073466 | I16: ='Nutrient balance'!E22 -> 0.16270745 | J16: =IF(G16>=$F16,"✓","✗") -> ✓ | K16: =IF(H16>=$F16,"✓","✗") -> ✓ | L16: =IF(I16>=$F16,"✓","✗") -> ✗ | M16: (P in fish + oysters + macroalgae) / P in feed
A17: C3 | B17: Circularity | C17: Net N released to water | D17: kg N/t | E17: lower | F17: 60 | G17: ='Nutrient balance'!C14 -> 54.738487 | H17: ='Nutrient balance'!D14 -> -3.7987421 | I17: ='Nutrient balance'!E14 -> 95.929607 | J17: =IF(G17<=$F17,"✓","✗") -> ✓ | K17: =IF(H17<=$F17,"✓","✗") -> ✓ | L17: =IF(I17<=$F17,"✓","✗") -> ✗ | M17: net N released per pond x scaling factor
A18: C4 | B18: Circularity | C18: Fish feed conversion ratio | D18: kg/kg | E18: lower | F18: 1.75 | G18: =Inventory!C26 -> 1.7179254 | H18: =Inventory!D26 -> 1.3692308 | I18: =Inventory!E26 -> 1.7883331 | J18: =IF(G18<=$F18,"✓","✗") -> ✓ | K18: =IF(H18<=$F18,"✓","✗") -> ✓ | L18: =IF(I18<=$F18,"✓","✗") -> ✗ | M18: feed / fish weight gain
