Workbook

Sheet README
A1: IMTA project: Goal & scope -> LCI -> LCIA -> Allocation -> KPI framework -> Results
A2: ILLUSTRATIVE TEACHING EXAMPLE - invented numbers, not Greencolab data and not real ecoinvent factors.
A4: Tabs (work left to right)
A5: 1. Goal & scope - functional unit, boundaries, method, allocation, cut-offs, assumptions.
A6: 1b. Metadata - project info and, per flow: source, data type, ecoinvent provider, location and pedigree data quality scores.
A7: 2. Parameters - nutrient contents, feed recipe, prices, diesel density and emission factor, distance.
A8: 3. LCI - inventory for one year, 2 scenarios: A fish monoculture, C IMTA (fish + seaweed + mussels) with seaweed residues composted and mussel shells reused as lime. Same structure as the openLCA model (feed as 5 ingredients, diesel in kg + combustion CO2).
A9: 4. Nutrient balance - where N and P from the feed go. Feeds the emission rows of the LCI.
A10: 5. Factors - impact per unit of each flow (stand-in for ecoinvent/EF values).
A11: 6. LCIA - impact = LCI amount x factor, per category, with hotspot shares and a chart.
A12: 6b. Contribution analysis - impacts grouped by contributor (feed, electricity, boat fuel, ropes, transport, direct emissions) with stacked charts and a pie chart.
A13: 7. Allocation - split between fish, seaweed, mussels by mass and by economic value.
... A25: - Parameters: FCR in literature for sea bream is about 1.7-2.0. Raise feed in LCI from 60,000 to 80,000 kg and see the effect.

Sheet Goal & scope
A1: Life cycle assessment of fish monoculture and IMTA aquaculture - goal and scope (ISO 14040/44)
A2: ILLUSTRATIVE TEACHING EXAMPLE - invented numbers, not Greencolab data and not real ecoinvent factors.
A4: Item | B4: Choice in this model | C4: Why / note
A5: Goal | B5: Compare fish monoculture with IMTA including valorisation of seaweed residues and mussel shells, to support a farm design decision | C5: Decision support, as in cirKPI
A6: Functional unit | B6: 1 kg fresh sea bream at the farm gate (plus transport to market) | C6: Fish is the determining product and is equal in all scenarios
A7: Reference flow | B7: 40,000 kg sea bream per year | C7: One year of farm operation
A8: System boundary | B8: Cradle to farm gate + transport to market | C8: Excludes processing, retail, consumer, end of life
A9: Co-products | B9: Seaweed and mussels (scenarios B and C) | C9: Handled by allocation
A10: Allocation | B10: Economic (default); mass shown for comparison | C10: Results are sensitive to this choice - see Allocation tab
A11: Impact method | B11: EF 3.x: climate change, marine eutrophication, energy demand | C11: Subset of EF categories most relevant for aquaculture
A12: Background data | B12: ecoinvent 3.7 cut-off (in openLCA model); illustrative factors in this workbook | C12: Factors tab
A13: Cut-offs | B13: Fish juveniles and mussel seed excluded | C13: No suitable dataset; mussel seed is wild-collected
A14: Feed | B14: Proxy recipe of 5 ingredients | C14: Feed milling energy excluded
A15: Diesel | B15: Production (ecoinvent) + direct CO2 from combustion | C15: 3.16 kg CO2 per kg diesel
... A20: Not modelled | B20: Mussel biodeposits, fish processing waste | C20: Biodeposits would need a deposit feeder (4th species)

Sheet Metadata
A1: Metadata - documentation of every flow and data choice
A2: ILLUSTRATIVE TEACHING EXAMPLE - invented numbers, not Greencolab data and not real ecoinvent factors.
A4: Project metadata
A5: Project | B5: IMTA farm LCA - monoculture vs IMTA (teaching example)
A6: Author | B6: Komal Mallesh Chougule
A7: Version | B7: v1.0
A8: Date | B8: 2026-10-23
A9: Standard | B9: ISO 14040/44
A10: Functional unit | B10: 1 kg fresh sea bream at farm gate, incl. transport to market
A11: Scenarios | B11: A: fish monoculture; B: IMTA (fish + seaweed + mussels)
A12: Reference period | B12: 1 year of operation
A13: Background database | B13: ecoinvent 3.7 cut-off (openLCA model); illustrative factors in this workbook
A14: Impact method | B14: EF 3.x
A15: Allocation | B15: Economic (default), mass for sensitivity
A16: Status | B16: Illustrative - activity data and factors are not measured or database values
A18: Flow metadata (pedigree scores 1 = best, 5 = worst)
A19: Flow | B19: Flow type | C19: Unit | D19: Amount scenario B | E19: Amount source | F19: Data type | G19: ecoinvent provider (openLCA) | H19: Location | I19: Factor source | J19: Reliability | K19: Completeness | L19: Temporal | M19: Geographical | N19: Technological | O19: Data quality (mean) | P19: Notes / assumptions
A20: Fish feed (total) | B20: activity | C20: kg | D20: =LCI!D6 -> 60000 | E20: Assumed FCR 1.5 | F20: Assumption | G20: - (split into 5 ingredients) | H20: - | I20: - | J20: 4 | K20: 3 | L20: 2 | M20: 3 | N20: 3 | O20: =AVERAGE(J20:N20) -> 3 | P20: Literature FCR for sea bream about 1.7-2.0
A21: Fishmeal, 63-65% protein | B21: technosphere | C21: kg | D21: =LCI!D11 -> 15000 | E21: Feed x recipe share | F21: Calculated | G21: fishmeal and fish oil production | H21: PE | I21: Illustrative | J21: 3 | K21: 3 | L21: 3 | M21: 3 | N21: 3 | O21: =AVERAGE(J21:N21) -> 3 | P21: Recipe share 25%
A22: Fish oil, from anchovy | B22: technosphere | C22: kg | D22: =LCI!D12 -> 6000 | E22: Feed x recipe share | F22: Calculated | G22: market for fish oil | H22: GLO | I22: Illustrative | J22: 3 | K22: 3 | L22: 3 | M22: 3 | N22: 3 | O22: =AVERAGE(J22:N22) -> 3 | P22: Recipe share 10%
A23: Soybean meal | B23: technosphere | C23: kg | D23: =LCI!D13 -> 18000 | E23: Feed x recipe share | F23: Calculated | G23: soybean meal and crude oil production | H23: BR | I23: Illustrative | J23: 3 | K23: 3 | L23: 3 | M23: 3 | N23: 3 | O23: =AVERAGE(J23:N23) -> 3 | P23: Land-use change can dominate
A24: Wheat grain, feed | B24: technosphere | C24: kg | D24: =LCI!D14 -> 15000 | E24: Feed x recipe share | F24: Calculated | G24: market for wheat grain, feed | H24: GLO | I24: Illustrative | J24: 3 | K24: 3 | L24: 3 | M24: 3 | N24: 3 | O24: =AVERAGE(J24:N24) -> 3 | P24: Recipe share 25%
A25: Rape oil, crude | B25: technosphere | C25: kg | D25: =LCI!D15 -> 6000 | E25: Feed x recipe share | F25: Calculated | G25: market for rape oil, crude | H25: CH (to change to RoW) | I25: Illustrative | J25: 3 | K25: 3 | L25: 3 | M25: 4 | N25: 3 | O25: =AVERAGE(J25:N25) -> 3.2 | P25: Provider chosen by auto-link
A26: Electricity, low voltage | B26: technosphere | C26: kWh | D26: =LCI!D16 -> 120000 | E26: Assumed farm demand | F26: Assumption | G26: market for electricity, low voltage | H26: PT | I26: Illustrative | J26: 4 | K26: 3 | L26: 2 | M26: 1 | N26: 2 | O26: =AVERAGE(J26:N26) -> 2.4 | P26: Pumps and aeration
A27: Diesel | B27: technosphere | C27: kg | D27: =LCI!D17 -> 3360 | E27: Litres x 0.84 kg/L | F27: Calculated | G27: market for diesel | H27: Europe without Switzerland | I27: Illustrative | J27: 4 | K27: 3 | L27: 2 | M27: 2 | N27: 2 | O27: =AVERAGE(J27:N27) -> 2.6 | P27: Production only
A28: Polypropylene, granulate | B28: technosphere | C28: kg | D28: =LCI!D18 -> 800 | E28: Assumed rope and net mass | F28: Assumption | G28: polypropylene production | H28: RoW | I28: Illustrative | J28: 4 | K28: 3 | L28: 3 | M28: 3 | N28: 3 | O28: =AVERAGE(J28:N28) -> 3.2 | P28: Rope extrusion not included
A29: Transport, freight, lorry | B29: technosphere | C29: t*km | D29: =LCI!D19 -> 34500 | E29: Harvest t x 300 km | F29: Calculated | G29: transport, freight, lorry | H29: RoW (to change to RER) | I29: Illustrative | J29: 3 | K29: 3 | L29: 2 | M29: 3 | N29: 2 | O29: =AVERAGE(J29:N29) -> 2.6 | P29: Distance assumed
A30: Sea bream, fresh | B30: product | C30: kg | D30: =LCI!D21 -> 40000 | E30: Assumed harvest | F30: Assumption | G30: - (reference product) | H30: PT | I30: - | J30: 3 | K30: 2 | L30: 2 | M30: 1 | N30: 2 | O30: =AVERAGE(J30:N30) -> 2 | P30: Reference flow
A31: Seaweed, fresh | B31: co-product | C31: kg | D31: =LCI!D22 -> 50000 | E31: Assumed harvest | F31: Assumption | G31: - | H31: PT | I31: - | J31: 4 | K31: 3 | L31: 2 | M31: 1 | N31: 2 | O31: =AVERAGE(J31:N31) -> 2.4 | P31: Wet weight
A32: Mussels, fresh | B32: co-product | C32: kg | D32: =LCI!D23 -> 25000 | E32: Assumed harvest | F32: Assumption | G32: - | H32: PT | I32: - | J32: 4 | K32: 3 | L32: 2 | M32: 1 | N32: 2 | O32: =AVERAGE(J32:N32) -> 2.4 | P32: Incl. shell
A33: Nitrogen, to ocean | B33: elementary | C33: kg | D33: =LCI!D26 -> 2450 | E33: Nutrient mass balance | F33: Calculated | G33: - (EF elementary flow) | H33: PT | I33: EF characterisation | J33: 3 | K33: 3 | L33: 2 | M33: 2 | N33: 3 | O33: =AVERAGE(J33:N33) -> 2.6 | P33: Feed N minus N in all products
A34: Phosphorus, to ocean | B34: elementary | C34: kg | D34: =LCI!D27 -> 465 | E34: Nutrient mass balance | F34: Calculated | G34: - (EF elementary flow) | H34: PT | I34: EF characterisation | J34: 3 | K34: 3 | L34: 2 | M34: 2 | N34: 3 | O34: =AVERAGE(J34:N34) -> 2.6 | P34: Not in EF marine eutrophication
A35: Carbon dioxide, fossil | B35: elementary | C35: kg | D35: =LCI!D28 -> 10617.6 | E35: Diesel kg x 3.16 | F35: Calculated | G35: - (combustion) | H35: PT | I35: Stoichiometric | J35: 2 | K35: 2 | L35: 1 | M35: 1 | N35: 2 | O35: =AVERAGE(J35:N35) -> 1.6 | P35: Direct boat emissions
A36: Fish juveniles | B36: cut-off | C36: piece | D36: =LCI!D8 -> 30000 | E36: Assumed stocking | F36: Assumption | G36: - (excluded) | H36: - | I36: - | J36: 4 | K36: 4 | L36: 3 | M36: 3 | N36: 3 | O36: =AVERAGE(J36:N36) -> 3.4 | P36: No dataset; excluded
A37: Mussel seed | B37: cut-off | C37: kg | D37: =LCI!D9 -> 2000 | E37: Assumed | F37: Assumption | G37: - (excluded) | H37: - | I37: - | J37: 4 | K37: 4 | L37: 3 | M37: 3 | N37: 3 | O37: =AVERAGE(J37:N37) -> 3.4 | P37: Wild-collected; excluded
A39: Pedigree matrix (Weidema): 1 = very good, 5 = poor, per indicator.
A40: Green = good (<=2.5), yellow = fair, red = poor (>=3.5): poor-quality flows with a high contribution are the priority for better data.
A41: Data type: Calculated = derived by formula from other data; Assumption = estimate to be replaced by measured farm data.

Sheet Parameters
A1: Parameters
A2: ILLUSTRATIVE TEACHING EXAMPLE - invented numbers, not Greencolab data and not real ecoinvent factors.
A4: Parameter | B4: Value | C4: Unit | D4: Note | E4: Source / status
A5: Feed recipe: fishmeal | B5: 0.25 | C5: share | D5: proxy recipe | E5: Assumption (illustrative) - not taken from a specific source
A6: Feed recipe: fish oil | B6: 0.1 | C6: share | E6: Assumption (illustrative) - not taken from a specific source
A7: Feed recipe: soybean meal | B7: 0.3 | C7: share | E7: Assumption (illustrative) - not taken from a specific source
A8: Feed recipe: wheat grain | B8: 0.25 | C8: share | E8: Assumption (illustrative) - not taken from a specific source
A9: Feed recipe: rapeseed oil | B9: 0.1 | C9: share | E9: Assumption (illustrative) - not taken from a specific source
A10: N content of feed | B10: 0.07 | C10: kg N/kg | E10: Assumption (illustrative) - not taken from a specific source; feed ~44% crude protein / 6.25
A11: P content of feed | B11: 0.012 | C11: kg P/kg | E11: Assumption (illustrative) - not taken from a specific source
A12: N content of fish | B12: 0.03 | C12: kg N/kg | D12: fresh weight | E12: Assumption (illustrative) - not taken from a specific source; implies 29% N retention - compare Checked vs Nederlof et al. 2021 (Rev. Aquacult.), via Global Seafood Alliance 2022: fish retain ~43% N, 24% P (salmon); open-water IMTA extractive species recover ~7% N, 16% P
A13: P content of fish | B13: 0.005 | C13: kg P/kg | E13: Assumption (illustrative) - not taken from a specific source; implies 28% P retention - compare Checked vs Nederlof et al. 2021 (Rev. Aquacult.), via Global Seafood Alliance 2022: fish retain ~43% N, 24% P (salmon); open-water IMTA extractive species recover ~7% N, 16% P
A14: N content of seaweed | B14: 0.005 | C14: kg N/kg | D14: fresh weight | E14: Assumption (illustrative) - not taken from a specific source; recovery check: Checked vs Nederlof et al. 2021 (Rev. Aquacult.), via Global Seafood Alliance 2022: fish retain ~43% N, 24% P (salmon); open-water IMTA extractive species recover ~7% N, 16% P
A15: P content of seaweed | B15: 0.0005 | C15: kg P/kg | E15: Assumption (illustrative) - not taken from a specific source
A16: N content of mussels | B16: 0.01 | C16: kg N/kg | D16: incl. shell | E16: Assumption (illustrative) - not taken from a specific source; recovery check: Checked vs Nederlof et al. 2021 (Rev. Aquacult.), via Global Seafood Alliance 2022: fish retain ~43% N, 24% P (salmon); open-water IMTA extractive species recover ~7% N, 16% P
A17: P content of mussels | B17: 0.001 | C17: kg P/kg | E17: Assumption (illustrative) - not taken from a specific source
A18: Price fish | B18: 7 | C18: EUR/kg | D18: farm gate | E18: Assumption (illustrative) - not taken from a specific source
A19: Price seaweed | B19: 1.5 | C19: EUR/kg | E19: Assumption (illustrative) - not taken from a specific source
A20: Price mussels | B20: 2.5 | C20: EUR/kg | E20: Assumption (illustrative) - not taken from a specific source
A21: Diesel density | B21: 0.84 | C21: kg/L | E21: Assumption (illustrative) - not taken from a specific source
A22: CO2 from diesel combustion | B22: 3.16 | C22: kg CO2/kg diesel | E22: Assumption (illustrative) - not taken from a specific source
A23: Transport distance to market | B23: 300 | C23: km | D23: lorry | E23: Assumption (illustrative) - not taken from a specific source
A24: Mussel shell share of live weight | B24: 0.4 | C24: kg/kg | D24: shells valorised in C | E24: Assumption (illustrative) - not taken from a specific source; rough check: shell about one third of total weight in M. galloprovincialis (Azizi et al. 2020, EasyChair preprint 2857)
A25: Electricity for shell crushing | B25: 20 | C25: kWh/t shell | E25: Assumption (illustrative) - not taken from a specific source
A26: Transport distance shells and residues | B26: 50 | C26: km | D26: to lime / compost user | E26: Assumption (illustrative) - not taken from a specific source
A27: Limestone substituted per kg shell | B27: 1 | C27: kg/kg | D27: CaCO3 1:1 | E27: Assumption (illustrative) - not taken from a specific source
A28: Mineral N fertiliser substituted per kg compost N | B28: 0.5 | C28: kg/kg | D28: plant-available share | E28: Assumption (illustrative) - not taken from a specific source
A29: N lost to water from composting and use | B29: 0.1 | C29: kg/kg N | E29: Assumption (illustrative) - not taken from a specific source
A30: Seaweed residues generated (trimmings, broken fronds) | B30: 10000 | C30: kg/yr | D30: left in the sea in B, collected in C | E30: Assumption (illustrative) - not taken from a specific source
A31: Check: recipe shares sum | B31: =SUM(B5:B9) -> 1

Sheet LCI
A1: Life Cycle Inventory - one year of farm operation
A2: ILLUSTRATIVE TEACHING EXAMPLE - invented numbers, not Greencolab data and not real ecoinvent factors.
A4: Flow | B4: Unit | C4: A: Fish monoculture | D4: C: IMTA + waste valorisation | E4: Type | F4: Note | H4: Source / status
A5: Activity data (entered by the farm)
A6: Fish feed (total) | B6: kg | C6: 60000 | D6: 60000 | F6: activity | G6: FCR = feed/fish | H6: Assumption (illustrative) - not taken from a specific source; Checked vs Garcia Garcia et al. 2016 (Sustainability 8:1228): FCR about 2, 1.7 tested - 1.5 here is optimistic
A7: Diesel used by boats | B7: L | C7: 3000 | D7: 4000 | F7: activity | H7: Assumption (illustrative) - not taken from a specific source
A8: Fish juveniles | B8: piece | C8: 30000 | D8: 30000 | F8: activity | G8: cut-off | H8: Assumption (illustrative) - not taken from a specific source
A9: Mussel seed | B9: kg | C9: 0 | D9: 2000 | F9: activity | G9: cut-off, wild-collected | H9: Assumption (illustrative) - not taken from a specific source
A10: Inputs from technosphere (linked to ecoinvent in openLCA)
A11: Fishmeal, 63-65% protein | B11: kg | C11: =C6*Parameters!$B$5 -> 15000 | D11: =D6*Parameters!$B$5 -> 15000 | F11: technosphere | G11: market/production, PE | H11: Calculated by formula from Parameters
A12: Fish oil, from anchovy | B12: kg | C12: =C6*Parameters!$B$6 -> 6000 | D12: =D6*Parameters!$B$6 -> 6000 | F12: technosphere | G12: market, GLO | H12: Calculated by formula from Parameters
A13: Soybean meal | B13: kg | C13: =C6*Parameters!$B$7 -> 18000 | D13: =D6*Parameters!$B$7 -> 18000 | F13: technosphere | G13: BR | H13: Calculated by formula from Parameters
A14: Wheat grain, feed | B14: kg | C14: =C6*Parameters!$B$8 -> 15000 | D14: =D6*Parameters!$B$8 -> 15000 | F14: technosphere | G14: market, GLO | H14: Calculated by formula from Parameters
A15: Rape oil, crude | B15: kg | C15: =C6*Parameters!$B$9 -> 6000 | D15: =D6*Parameters!$B$9 -> 6000 | F15: technosphere | G15: market | H15: Calculated by formula from Parameters
A16: Electricity, low voltage | B16: kWh | C16: 100000 | D16: 120000 | F16: technosphere | G16: market, PT | H16: Assumption (illustrative) - not taken from a specific source
A17: Diesel | B17: kg | C17: =C7*Parameters!$B$21 -> 2520 | D17: =D7*Parameters!$B$21 -> 3360 | F17: technosphere | G17: Europe without Switzerland | H17: Calculated by formula from Parameters
A18: Polypropylene, granulate | B18: kg | C18: 300 | D18: 800 | F18: technosphere | G18: ropes and nets | H18: Assumption (illustrative) - not taken from a specific source
A19: Transport, freight, lorry | B19: t*km | C19: =C24/1000*Parameters!$B$23 -> 12000 | D19: =D24/1000*Parameters!$B$23 -> 34500 | F19: technosphere | G19: harvest t x distance | H19: Calculated by formula from Parameters
A20: Products (outputs)
A21: Sea bream, fresh (reference) | B21: kg | C21: 40000 | D21: 40000 | F21: product | H21: Assumption (illustrative) - not taken from a specific source
A22: Seaweed, fresh | B22: kg | C22: 0 | D22: 50000 | F22: product | H22: Assumption (illustrative) - not taken from a specific source
A23: Mussels, fresh | B23: kg | C23: 0 | D23: 25000 | F23: product | H23: Assumption (illustrative) - not taken from a specific source
A24: Total harvest | B24: kg | C24: =SUM(C21:C23) -> 40000 | D24: =SUM(D21:D23) -> 115000 | H24: Calculated by formula from Parameters
A25: Elementary flows (emissions)
A26: Nitrogen, to ocean | B26: kg N | C26: ='Nutrient balance'!C11 -> 3000 | D26: ='Nutrient balance'!D11 -> 2450 | F26: elementary | G26: water/ocean | H26: Calculated by formula from Parameters
A27: Phosphorus, to ocean | B27: kg P | C27: ='Nutrient balance'!C19 -> 520 | D27: ='Nutrient balance'!D19 -> 465 | F27: elementary | G27: water/ocean | H27: Calculated by formula from Parameters
A28: Carbon dioxide, fossil (diesel combustion) | B28: kg CO2 | C28: =C17*Parameters!$B$22 -> 7963.2 | D28: =D17*Parameters!$B$22 -> 10617.6 | F28: elementary | G28: air/unspecified | H28: Calculated by formula from Parameters
A30: Waste valorisation (scenario C)
A31: Seaweed residues collected | B31: kg | C31: 0 | D31: 10000 | F31: activity | G31: composted, used as soil amendment | H31: Assumption (illustrative) - not taken from a specific source
A32: Mussel shells valorised | B32: kg | C32: =IF(C31>0,C23*Parameters!$B$24,0) -> 0 | D32: =IF(D31>0,D23*Parameters!$B$24,0) -> 10000 | F32: activity | G32: crushed, used as lime | H32: Calculated by formula from Parameters
A33: Electricity, shell crushing | B33: kWh | C33: =C32/1000*Parameters!$B$25 -> 0 | D33: =D32/1000*Parameters!$B$25 -> 200 | F33: technosphere | G33: market, PT | H33: Calculated by formula from Parameters
A34: Transport, shells and residues | B34: t*km | C34: =(C31+C32)/1000*Parameters!$B$26 -> 0 | D34: =(D31+D32)/1000*Parameters!$B$26 -> 1000 | F34: technosphere | G34: lorry | H34: Calculated by formula from Parameters
A35: Composting of seaweed residues | B35: kg | C35: =C31 -> 0 | D35: =D31 -> 10000 | F35: technosphere | G35: treatment process | H35: Calculated by formula from Parameters
A36: Ground limestone (avoided) | B36: kg | C36: =-C32*Parameters!$B$27 -> 0 | D36: =-D32*Parameters!$B$27 -> -10000 | F36: avoided product | G36: negative = credit | H36: Calculated by formula from Parameters
A37: Mineral N fertiliser (avoided) | B37: kg N | C37: =-C31*Parameters!$B$14*Parameters!$B$28 -> 0 | D37: =-D31*Parameters!$B$14*Parameters!$B$28 -> -25 | F37: avoided product | G37: negative = credit | H37: Calculated by formula from Parameters
A38: Nitrogen to water from compost use | B38: kg N | C38: =C31*Parameters!$B$14*Parameters!$B$29 -> 0 | D38: =D31*Parameters!$B$14*Parameters!$B$29 -> 5 | F38: elementary | G38: water/unspecified | H38: Calculated by formula from Parameters
A40: Not modelled: mussel biodeposits (faeces) - using them would need a deposit feeder (e.g. sea cucumbers).

Sheet Nutrient balance
A1: Nutrient balance - where do N and P from the feed go?
A2: ILLUSTRATIVE TEACHING EXAMPLE - invented numbers, not Greencolab data and not real ecoinvent factors.
A4: Item | B4: Unit | C4: A: Fish monoculture | D4: C: IMTA + waste valorisation
A5: N in feed | B5: kg N | C5: =LCI!C6*Parameters!$B$10 -> 4200 | D5: =LCI!D6*Parameters!$B$10 -> 4200
A6: N kept in fish | B6: kg N | C6: =LCI!C21*Parameters!$B$12 -> 1200 | D6: =LCI!D21*Parameters!$B$12 -> 1200
A7: N taken up by seaweed (incl. collected residues) | B7: kg N | C7: =(LCI!C22+LCI!C31)*Parameters!$B$14 -> 0 | D7: =(LCI!D22+LCI!D31)*Parameters!$B$14 -> 300
A8: N taken up by mussels | B8: kg N | C8: =LCI!C23*Parameters!$B$16 -> 0 | D8: =LCI!D23*Parameters!$B$16 -> 250
A9: N released by fish (feed - fish) | B9: kg N | C9: =C5-C6 -> 3000 | D9: =D5-D6 -> 3000
A10: N recovered by extractive species | B10: kg N | C10: =C7+C8 -> 0 | D10: =D7+D8 -> 550
A11: N emitted to sea | B11: kg N | C11: =C9-C10 -> 3000 | D11: =D9-D10 -> 2450
A12: Phosphorus
A13: P in feed | B13: kg P | C13: =LCI!C6*Parameters!$B$11 -> 720 | D13: =LCI!D6*Parameters!$B$11 -> 720
A14: P kept in fish | B14: kg P | C14: =LCI!C21*Parameters!$B$13 -> 200 | D14: =LCI!D21*Parameters!$B$13 -> 200
A15: P taken up by seaweed (incl. collected residues) | B15: kg P | C15: =(LCI!C22+LCI!C31)*Parameters!$B$15 -> 0 | D15: =(LCI!D22+LCI!D31)*Parameters!$B$15 -> 30
A16: P taken up by mussels | B16: kg P | C16: =LCI!C23*Parameters!$B$17 -> 0 | D16: =LCI!D23*Parameters!$B$17 -> 25
A17: P released by fish (feed - fish) | B17: kg P | C17: =C13-C14 -> 520 | D17: =D13-D14 -> 520
A18: P recovered by extractive species | B18: kg P | C18: =C15+C16 -> 0 | D18: =D15+D16 -> 55
A19: P emitted to sea | B19: kg P | C19: =C17-C18 -> 520 | D19: =D17-D18 -> 465

Sheet Factors
A1: Impact factors per unit of flow (stand-in for ecoinvent + EF values)
A2: ILLUSTRATIVE TEACHING EXAMPLE - invented numbers, not Greencolab data and not real ecoinvent factors.
A4: Flow | B4: Unit | C4: Climate change (kg CO2-eq/unit) | D4: Marine eutrophication (kg N-eq/unit) | E4: Energy demand (MJ/unit) | F4: Note | G4: Source / status
A5: Fishmeal, 63-65% protein | B5: kg | C5: 1.5 | D5: 0.02 | E5: 20 | G5: Illustrative round value - NOT from ecoinvent. Real values: see 'openLCA results' (ecoinvent 3.7 cut-off, EF 3.1)
A6: Fish oil, from anchovy | B6: kg | C6: 1.8 | D6: 0.02 | E6: 22 | G6: Illustrative round value - NOT from ecoinvent. Real values: see 'openLCA results' (ecoinvent 3.7 cut-off, EF 3.1)
A7: Soybean meal | B7: kg | C7: 1.5 | D7: 0.04 | E7: 8 | F7: land-use change can raise this strongly | G7: Illustrative round value - NOT from ecoinvent. Real values: see 'openLCA results' (ecoinvent 3.7 cut-off, EF 3.1)
A8: Wheat grain, feed | B8: kg | C8: 0.6 | D8: 0.03 | E8: 4 | G8: Illustrative round value - NOT from ecoinvent. Real values: see 'openLCA results' (ecoinvent 3.7 cut-off, EF 3.1)
A9: Rape oil, crude | B9: kg | C9: 2.5 | D9: 0.04 | E9: 20 | G9: Illustrative round value - NOT from ecoinvent. Real values: see 'openLCA results' (ecoinvent 3.7 cut-off, EF 3.1)
A10: Electricity, low voltage | B10: kWh | C10: 0.2 | D10: 0.0002 | E10: 9 | F10: PT grid | G10: Illustrative round value - NOT from ecoinvent. Real values: see 'openLCA results' (ecoinvent 3.7 cut-off, EF 3.1)
A11: Diesel | B11: kg | C11: 0.6 | D11: 0.001 | E11: 50 | F11: production only | G11: Illustrative round value - NOT from ecoinvent. Real values: see 'openLCA results' (ecoinvent 3.7 cut-off, EF 3.1)
A12: Polypropylene, granulate | B12: kg | C12: 2 | D12: 0.0005 | E12: 75 | G12: Illustrative round value - NOT from ecoinvent. Real values: see 'openLCA results' (ecoinvent 3.7 cut-off, EF 3.1)
A13: Transport, freight, lorry | B13: t*km | C13: 0.12 | D13: 0.0003 | E13: 1.8 | G13: Illustrative round value - NOT from ecoinvent. Real values: see 'openLCA results' (ecoinvent 3.7 cut-off, EF 3.1)
A14: Nitrogen, to ocean | B14: kg N | C14: 0 | D14: 1 | E14: 0 | F14: EF marine eutrophication counts N | G14: Illustrative round value - NOT from ecoinvent. Real values: see 'openLCA results' (ecoinvent 3.7 cut-off, EF 3.1)
A15: Phosphorus, to ocean | B15: kg P | C15: 0 | D15: 0 | E15: 0 | F15: P counts in freshwater eutrophication | G15: Illustrative round value - NOT from ecoinvent. Real values: see 'openLCA results' (ecoinvent 3.7 cut-off, EF 3.1)
A16: Carbon dioxide, fossil | B16: kg CO2 | C16: 1 | D16: 0 | E16: 0 | F16: by definition | G16: Illustrative round value - NOT from ecoinvent. Real values: see 'openLCA results' (ecoinvent 3.7 cut-off, EF 3.1)
A17: Electricity, shell crushing | B17: kWh | C17: 0.2 | D17: 0.0002 | E17: 9 | F17: PT grid | G17: Illustrative round value - NOT from ecoinvent. Real values: see 'openLCA results' (ecoinvent 3.7 cut-off, EF 3.1)
A18: Transport, shells and residues | B18: t*km | C18: 0.12 | D18: 0.0003 | E18: 1.8 | G18: Illustrative round value - NOT from ecoinvent. Real values: see 'openLCA results' (ecoinvent 3.7 cut-off, EF 3.1)
A19: Composting of seaweed residues | B19: kg | C19: 0.03 | D19: 0 | E19: 0.1 | F19: CH4/N2O from composting | G19: Illustrative round value - NOT from ecoinvent. Real values: see 'openLCA results' (ecoinvent 3.7 cut-off, EF 3.1)
A20: Ground limestone (avoided) | B20: kg | C20: 0.02 | D20: 1e-05 | E20: 0.3 | F20: credit when amount is negative | G20: Illustrative round value - NOT from ecoinvent. Real values: see 'openLCA results' (ecoinvent 3.7 cut-off, EF 3.1)
A21: Mineral N fertiliser (avoided) | B21: kg N | C21: 8 | D21: 0.01 | E21: 60 | F21: credit when amount is negative | G21: Illustrative round value - NOT from ecoinvent. Real values: see 'openLCA results' (ecoinvent 3.7 cut-off, EF 3.1)
A22: Nitrogen to water (compost) | B22: kg N | C22: 0 | D22: 1 | E22: 0 | G22: Illustrative round value - NOT from ecoinvent. Real values: see 'openLCA results' (ecoinvent 3.7 cut-off, EF 3.1)

Sheet LCIA
A1: Life Cycle Impact Assessment - farm total per year (impact = LCI x factor)
A2: ILLUSTRATIVE TEACHING EXAMPLE - invented numbers, not Greencolab data and not real ecoinvent factors.
A4: Flow | B4: Unit | C4: A: Fish monoculture | D4: C: IMTA + waste valorisation | E4: Share of total (C)
A5: Climate change
A6: Fishmeal, 63-65% protein | B6: kg CO2-eq | C6: =LCI!C11*Factors!$C$5 -> 22500 | D6: =LCI!D11*Factors!$C$5 -> 22500 | E6: =IFERROR(D6/D$24,0) -> 0.17753776
A7: Fish oil, from anchovy | B7: kg CO2-eq | C7: =LCI!C12*Factors!$C$6 -> 10800 | D7: =LCI!D12*Factors!$C$6 -> 10800 | E7: =IFERROR(D7/D$24,0) -> 0.085218127
A8: Soybean meal | B8: kg CO2-eq | C8: =LCI!C13*Factors!$C$7 -> 27000 | D8: =LCI!D13*Factors!$C$7 -> 27000 | E8: =IFERROR(D8/D$24,0) -> 0.21304532
A9: Wheat grain, feed | B9: kg CO2-eq | C9: =LCI!C14*Factors!$C$8 -> 9000 | D9: =LCI!D14*Factors!$C$8 -> 9000 | E9: =IFERROR(D9/D$24,0) -> 0.071015106
A10: Rape oil, crude | B10: kg CO2-eq | C10: =LCI!C15*Factors!$C$9 -> 15000 | D10: =LCI!D15*Factors!$C$9 -> 15000 | E10: =IFERROR(D10/D$24,0) -> 0.11835851
A11: Electricity, low voltage | B11: kg CO2-eq | C11: =LCI!C16*Factors!$C$10 -> 20000 | D11: =LCI!D16*Factors!$C$10 -> 24000 | E11: =IFERROR(D11/D$24,0) -> 0.18937362
A12: Diesel (production) | B12: kg CO2-eq | C12: =LCI!C17*Factors!$C$11 -> 1512 | D12: =LCI!D17*Factors!$C$11 -> 2016 | E12: =IFERROR(D12/D$24,0) -> 0.015907384
A13: Polypropylene, granulate | B13: kg CO2-eq | C13: =LCI!C18*Factors!$C$12 -> 600 | D13: =LCI!D18*Factors!$C$12 -> 1600 | E13: =IFERROR(D13/D$24,0) -> 0.012624908
A14: Transport, freight, lorry | B14: kg CO2-eq | C14: =LCI!C19*Factors!$C$13 -> 1440 | D14: =LCI!D19*Factors!$C$13 -> 4140 | E14: =IFERROR(D14/D$24,0) -> 0.032666949
A15: Nitrogen, to ocean | B15: kg CO2-eq | C15: =LCI!C26*Factors!$C$14 -> 0 | D15: =LCI!D26*Factors!$C$14 -> 0 | E15: =IFERROR(D15/D$24,0) -> 0
A16: Phosphorus, to ocean | B16: kg CO2-eq | C16: =LCI!C27*Factors!$C$15 -> 0 | D16: =LCI!D27*Factors!$C$15 -> 0 | E16: =IFERROR(D16/D$24,0) -> 0
A17: CO2 from diesel combustion | B17: kg CO2-eq | C17: =LCI!C28*Factors!$C$16 -> 7963.2 | D17: =LCI!D28*Factors!$C$16 -> 10617.6 | E17: =IFERROR(D17/D$24,0) -> 0.083778887
A18: Shell crushing electricity | B18: kg CO2-eq | C18: =LCI!C33*Factors!$C$17 -> 0 | D18: =LCI!D33*Factors!$C$17 -> 40 | E18: =IFERROR(D18/D$24,0) -> 0.00031562269
A19: Transport shells and residues | B19: kg CO2-eq | C19: =LCI!C34*Factors!$C$18 -> 0 | D19: =LCI!D34*Factors!$C$18 -> 120 | E19: =IFERROR(D19/D$24,0) -> 0.00094686808
A20: Composting seaweed residues | B20: kg CO2-eq | C20: =LCI!C35*Factors!$C$19 -> 0 | D20: =LCI!D35*Factors!$C$19 -> 300 | E20: =IFERROR(D20/D$24,0) -> 0.0023671702
A21: Avoided limestone (credit) | B21: kg CO2-eq | C21: =LCI!C36*Factors!$C$20 -> 0 | D21: =LCI!D36*Factors!$C$20 -> -200 | E21: =IFERROR(D21/D$24,0) -> -0.0015781135
A22: Avoided N fertiliser (credit) | B22: kg CO2-eq | C22: =LCI!C37*Factors!$C$21 -> 0 | D22: =LCI!D37*Factors!$C$21 -> -200 | E22: =IFERROR(D22/D$24,0) -> -0.0015781135
A23: N to water from compost | B23: kg CO2-eq | C23: =LCI!C38*Factors!$C$22 -> 0 | D23: =LCI!D38*Factors!$C$22 -> 0 | E23: =IFERROR(D23/D$24,0) -> 0
A24: Total climate change | B24: kg CO2-eq | C24: =SUM(C6:C23) -> 115815.2 | D24: =SUM(D6:D23) -> 126733.6
A25: of which feed (5 ingredients) | C25: =SUM(C6:C10) -> 84300 | D25: =SUM(D6:D10) -> 84300 | E25: =IFERROR(D25/D24,0) -> 0.66517482
A27: Marine eutrophication
A28: Fishmeal, 63-65% protein | B28: kg N-eq | C28: =LCI!C11*Factors!$D$5 -> 300 | D28: =LCI!D11*Factors!$D$5 -> 300 | E28: =IFERROR(D28/D$46,0) -> 0.069394647
A29: Fish oil, from anchovy | B29: kg N-eq | C29: =LCI!C12*Factors!$D$6 -> 120 | D29: =LCI!D12*Factors!$D$6 -> 120 | E29: =IFERROR(D29/D$46,0) -> 0.027757859
A30: Soybean meal | B30: kg N-eq | C30: =LCI!C13*Factors!$D$7 -> 720 | D30: =LCI!D13*Factors!$D$7 -> 720 | E30: =IFERROR(D30/D$46,0) -> 0.16654715
A31: Wheat grain, feed | B31: kg N-eq | C31: =LCI!C14*Factors!$D$8 -> 450 | D31: =LCI!D14*Factors!$D$8 -> 450 | E31: =IFERROR(D31/D$46,0) -> 0.10409197
A32: Rape oil, crude | B32: kg N-eq | C32: =LCI!C15*Factors!$D$9 -> 240 | D32: =LCI!D15*Factors!$D$9 -> 240 | E32: =IFERROR(D32/D$46,0) -> 0.055515718
A33: Electricity, low voltage | B33: kg N-eq | C33: =LCI!C16*Factors!$D$10 -> 20 | D33: =LCI!D16*Factors!$D$10 -> 24 | E33: =IFERROR(D33/D$46,0) -> 0.0055515718
A34: Diesel (production) | B34: kg N-eq | C34: =LCI!C17*Factors!$D$11 -> 2.52 | D34: =LCI!D17*Factors!$D$11 -> 3.36 | E34: =IFERROR(D34/D$46,0) -> 0.00077722005
A35: Polypropylene, granulate | B35: kg N-eq | C35: =LCI!C18*Factors!$D$12 -> 0.15 | D35: =LCI!D18*Factors!$D$12 -> 0.4 | E35: =IFERROR(D35/D$46,0) -> 9.2526196e-05
A36: Transport, freight, lorry | B36: kg N-eq | C36: =LCI!C19*Factors!$D$13 -> 3.6 | D36: =LCI!D19*Factors!$D$13 -> 10.35 | E36: =IFERROR(D36/D$46,0) -> 0.0023941153
A37: Nitrogen, to ocean | B37: kg N-eq | C37: =LCI!C26*Factors!$D$14 -> 3000 | D37: =LCI!D26*Factors!$D$14 -> 2450 | E37: =IFERROR(D37/D$46,0) -> 0.56672295
A38: Phosphorus, to ocean | B38: kg N-eq | C38: =LCI!C27*Factors!$D$15 -> 0 | D38: =LCI!D27*Factors!$D$15 -> 0 | E38: =IFERROR(D38/D$46,0) -> 0
A39: CO2 from diesel combustion | B39: kg N-eq | C39: =LCI!C28*Factors!$D$16 -> 0 | D39: =LCI!D28*Factors!$D$16 -> 0 | E39: =IFERROR(D39/D$46,0) -> 0
A40: Shell crushing electricity | B40: kg N-eq | C40: =LCI!C33*Factors!$D$17 -> 0 | D40: =LCI!D33*Factors!$D$17 -> 0.04 | E40: =IFERROR(D40/D$46,0) -> 9.2526196e-06
A41: Transport shells and residues | B41: kg N-eq | C41: =LCI!C34*Factors!$D$18 -> 0 | D41: =LCI!D34*Factors!$D$18 -> 0.3 | E41: =IFERROR(D41/D$46,0) -> 6.9394647e-05
A42: Composting seaweed residues | B42: kg N-eq | C42: =LCI!C35*Factors!$D$19 -> 0 | D42: =LCI!D35*Factors!$D$19 -> 0 | E42: =IFERROR(D42/D$46,0) -> 0
...

Sheet Contribution analysis
A1: Contribution analysis - which part of the system causes the impact?
A2: ILLUSTRATIVE TEACHING EXAMPLE - invented numbers, not Greencolab data and not real ecoinvent factors.
A4: Climate change (kg CO2-eq per year, whole farm)
A5: Contributor | B5: A: Fish monoculture | C5: C: IMTA + waste valorisation | D5: Share A | E5: Share C
A6: Feed (5 ingredients) | B6: =LCIA!C6+LCIA!C7+LCIA!C8+LCIA!C9+LCIA!C10 -> 84300 | C6: =LCIA!D6+LCIA!D7+LCIA!D8+LCIA!D9+LCIA!D10 -> 84300 | D6: =IFERROR(B6/B$14,0) -> 0.72788373 | E6: =IFERROR(C6/C$14,0) -> 0.66517482
A7: Electricity | B7: =LCIA!C11 -> 20000 | C7: =LCIA!D11 -> 24000 | D7: =IFERROR(B7/B$14,0) -> 0.1726889 | E7: =IFERROR(C7/C$14,0) -> 0.18937362
A8: Boat fuel (diesel + combustion) | B8: =LCIA!C12+LCIA!C17 -> 9475.2 | C8: =LCIA!D12+LCIA!D17 -> 12633.6 | D8: =IFERROR(B8/B$14,0) -> 0.081813095 | E8: =IFERROR(C8/C$14,0) -> 0.099686271
A9: Ropes and nets (PP) | B9: =LCIA!C13 -> 600 | C9: =LCIA!D13 -> 1600 | D9: =IFERROR(B9/B$14,0) -> 0.0051806671 | E9: =IFERROR(C9/C$14,0) -> 0.012624908
A10: Transport to market | B10: =LCIA!C14 -> 1440 | C10: =LCIA!D14 -> 4140 | D10: =IFERROR(B10/B$14,0) -> 0.012433601 | E10: =IFERROR(C10/C$14,0) -> 0.032666949
A11: Direct N and P emissions | B11: =LCIA!C15+LCIA!C16 -> 0 | C11: =LCIA!D15+LCIA!D16 -> 0 | D11: =IFERROR(B11/B$14,0) -> 0 | E11: =IFERROR(C11/C$14,0) -> 0
A12: Waste valorisation processes | B12: =LCIA!C18+LCIA!C19+LCIA!C20+LCIA!C23 -> 0 | C12: =LCIA!D18+LCIA!D19+LCIA!D20+LCIA!D23 -> 460 | D12: =IFERROR(B12/B$14,0) -> 0 | E12: =IFERROR(C12/C$14,0) -> 0.003629661
A13: Credits: avoided lime and fertiliser | B13: =LCIA!C21+LCIA!C22 -> 0 | C13: =LCIA!D21+LCIA!D22 -> -400 | D13: =IFERROR(B13/B$14,0) -> 0 | E13: =IFERROR(C13/C$14,0) -> -0.0031562269
A14: Total | B14: =SUM(B6:B13) -> 115815.2 | C14: =SUM(C6:C13) -> 126733.6
A17: Marine eutrophication (kg N-eq per year, whole farm)
A18: Contributor | B18: A: Fish monoculture | C18: C: IMTA + waste valorisation | D18: Share A | E18: Share C
A19: Feed (5 ingredients) | B19: =LCIA!C28+LCIA!C29+LCIA!C30+LCIA!C31+LCIA!C32 -> 1830 | C19: =LCIA!D28+LCIA!D29+LCIA!D30+LCIA!D31+LCIA!D32 -> 1830 | D19: =IFERROR(B19/B$27,0) -> 0.37683242 | E19: =IFERROR(C19/C$27,0) -> 0.42330735
A20: Electricity | B20: =LCIA!C33 -> 20 | C20: =LCIA!D33 -> 24 | D20: =IFERROR(B20/B$27,0) -> 0.0041183872 | E20: =IFERROR(C20/C$27,0) -> 0.0055515718
A21: Boat fuel (diesel + combustion) | B21: =LCIA!C34+LCIA!C39 -> 2.52 | C21: =LCIA!D34+LCIA!D39 -> 3.36 | D21: =IFERROR(B21/B$27,0) -> 0.00051891678 | E21: =IFERROR(C21/C$27,0) -> 0.00077722005
A22: Ropes and nets (PP) | B22: =LCIA!C35 -> 0.15 | C22: =LCIA!D35 -> 0.4 | D22: =IFERROR(B22/B$27,0) -> 3.0887904e-05 | E22: =IFERROR(C22/C$27,0) -> 9.2526196e-05
A23: Transport to market | B23: =LCIA!C36 -> 3.6 | C23: =LCIA!D36 -> 10.35 | D23: =IFERROR(B23/B$27,0) -> 0.00074130969 | E23: =IFERROR(C23/C$27,0) -> 0.0023941153
A24: Direct N and P emissions | B24: =LCIA!C37+LCIA!C38 -> 3000 | C24: =LCIA!D37+LCIA!D38 -> 2450 | D24: =IFERROR(B24/B$27,0) -> 0.61775807 | E24: =IFERROR(C24/C$27,0) -> 0.56672295
A25: Waste valorisation processes | B25: =LCIA!C40+LCIA!C41+LCIA!C42+LCIA!C45 -> 0 | C25: =LCIA!D40+LCIA!D41+LCIA!D42+LCIA!D45 -> 5.34 | D25: =IFERROR(B25/B$27,0) -> 0 | E25: =IFERROR(C25/C$27,0) -> 0.0012352247
A26: Credits: avoided lime and fertiliser | B26: =LCIA!C43+LCIA!C44 -> 0 | C26: =LCIA!D43+LCIA!D44 -> -0.35 | D26: =IFERROR(B26/B$27,0) -> 0 | E26: =IFERROR(C26/C$27,0) -> -8.0960422e-05
A27: Total | B27: =SUM(B19:B26) -> 4856.27 | C27: =SUM(C19:C26) -> 4323.1
A30: Energy demand (MJ per year, whole farm)
A31: Contributor | B31: A: Fish monoculture | C31: C: IMTA + waste valorisation | D31: Share A | E31: Share C
A32: Feed (5 ingredients) | B32: =LCIA!C50+LCIA!C51+LCIA!C52+LCIA!C53+LCIA!C54 -> 756000 | C32: =LCIA!D50+LCIA!D51+LCIA!D52+LCIA!D53+LCIA!D54 -> 756000 | D32: =IFERROR(B32/B$40,0) -> 0.41399704 | E32: =IFERROR(C32/C$40,0) -> 0.35556392
A33: Electricity | B33: =LCIA!C55 -> 900000 | C33: =LCIA!D55 -> 1080000 | D33: =IFERROR(B33/B$40,0) -> 0.49285362 | E33: =IFERROR(C33/C$40,0) -> 0.50794845
A34: Boat fuel (diesel + combustion) | B34: =LCIA!C56+LCIA!C61 -> 126000 | C34: =LCIA!D56+LCIA!D61 -> 168000 | D34: =IFERROR(B34/B$40,0) -> 0.068999507 | E34: =IFERROR(C34/C$40,0) -> 0.079014204
A35: Ropes and nets (PP) | B35: =LCIA!C57 -> 22500 | C35: =LCIA!D57 -> 60000 | D35: =IFERROR(B35/B$40,0) -> 0.012321341 | E35: =IFERROR(C35/C$40,0) -> 0.028219358
A36: Transport to market | B36: =LCIA!C58 -> 21600 | C36: =LCIA!D58 -> 62100 | D36: =IFERROR(B36/B$40,0) -> 0.011828487 | E36: =IFERROR(C36/C$40,0) -> 0.029207036
A37: Direct N and P emissions | B37: =LCIA!C59+LCIA!C60 -> 0 | C37: =LCIA!D59+LCIA!D60 -> 0 | D37: =IFERROR(B37/B$40,0) -> 0 | E37: =IFERROR(C37/C$40,0) -> 0
A38: Waste valorisation processes | B38: =LCIA!C62+LCIA!C63+LCIA!C64+LCIA!C67 -> 0 | C38: =LCIA!D62+LCIA!D63+LCIA!D64+LCIA!D67 -> 4600 | D38: =IFERROR(B38/B$40,0) -> 0 | E38: =IFERROR(C38/C$40,0) -> 0.0021634842
A39: Credits: avoided lime and fertiliser | B39: =LCIA!C65+LCIA!C66 -> 0 | C39: =LCIA!D65+LCIA!D66 -> -4500 | D39: =IFERROR(B39/B$40,0) -> 0 | E39: =IFERROR(C39/C$40,0) -> -0.0021164519
A40: Total | B40: =SUM(B32:B39) -> 1826100 | C40: =SUM(C32:C39) -> 2126200
A43: Reading: the largest share in each category is the hotspot - the place where improvement has the biggest effect.
A44: Climate: feed dominates. Eutrophication: direct nitrogen from the fish dominates, and IMTA reduces it. Waste valorisation (C) adds small processes and small credits - minor for climate.

Sheet Allocation
A1: Allocation - splitting the farm's impact between fish, seaweed and mussels
A2: ILLUSTRATIVE TEACHING EXAMPLE - invented numbers, not Greencolab data and not real ecoinvent factors.
A4: Item | B4: Unit | C4: A: Fish monoculture | D4: C: IMTA + waste valorisation
A5: Farm climate change | B5: kg CO2-eq | C5: =LCIA!C24 -> 115815.2 | D5: =LCIA!D24 -> 126733.6
A6: Farm marine eutrophication | B6: kg N-eq | C6: =LCIA!C46 -> 4856.27 | D6: =LCIA!D46 -> 4323.1
A7: Farm energy demand | B7: MJ | C7: =LCIA!C68 -> 1826100 | D7: =LCIA!D68 -> 2126200
A8: Mass allocation factors
A9: Mass share fish | B9: % | C9: =LCI!C21/LCI!C24 -> 1 | D9: =LCI!D21/LCI!D24 -> 0.34782609
A10: Mass share seaweed | B10: % | C10: =LCI!C22/LCI!C24 -> 0 | D10: =LCI!D22/LCI!D24 -> 0.43478261
A11: Mass share mussels | B11: % | C11: =LCI!C23/LCI!C24 -> 0 | D11: =LCI!D23/LCI!D24 -> 0.2173913
A12: Economic allocation factors
A13: Revenue fish | B13: EUR | C13: =LCI!C21*Parameters!$B$18 -> 280000 | D13: =LCI!D21*Parameters!$B$18 -> 280000
A14: Revenue seaweed | B14: EUR | C14: =LCI!C22*Parameters!$B$19 -> 0 | D14: =LCI!D22*Parameters!$B$19 -> 75000
A15: Revenue mussels | B15: EUR | C15: =LCI!C23*Parameters!$B$20 -> 0 | D15: =LCI!D23*Parameters!$B$20 -> 62500
A16: Total revenue | B16: EUR | C16: =SUM(C13:C15) -> 280000 | D16: =SUM(D13:D15) -> 417500
A17: Economic share fish | B17: % | C17: =C13/C16 -> 1 | D17: =D13/D16 -> 0.67065868
A18: Economic share seaweed | B18: % | C18: =C14/C16 -> 0 | D18: =D14/D16 -> 0.17964072
A19: Economic share mussels | B19: % | C19: =C15/C16 -> 0 | D19: =D15/D16 -> 0.1497006
A20: Results per kg product
A21: Climate change per kg fish - MASS | B21: kg CO2-eq/kg | C21: =C5*C9/LCI!C21 -> 2.89538 | D21: =D5*D9/LCI!D21 -> 1.1020313
A22: Climate change per kg fish - ECONOMIC | B22: kg CO2-eq/kg | C22: =C5*C17/LCI!C21 -> 2.89538 | D22: =D5*D17/LCI!D21 -> 2.1248747
A23: Climate change per kg seaweed - ECONOMIC | B23: kg CO2-eq/kg | C23: =IFERROR(C5*C18/LCI!C22,0) -> 0 | D23: =IFERROR(D5*D18/LCI!D22,0) -> 0.4553303
A24: Climate change per kg mussels - ECONOMIC | B24: kg CO2-eq/kg | C24: =IFERROR(C5*C19/LCI!C23,0) -> 0 | D24: =IFERROR(D5*D19/LCI!D23,0) -> 0.75888383
A25: Marine eutrophication per kg fish - ECONOMIC | B25: kg N-eq/kg | C25: =C6*C17/LCI!C21 -> 0.12140675 | D25: =D6*D17/LCI!D21 -> 0.072483114
A26: Energy demand per kg fish - ECONOMIC | B26: MJ/kg | C26: =C7*C17/LCI!C21 -> 45.6525 | D26: =D7*D17/LCI!D21 -> 35.648862
A28: Same farm and emissions, but the fish footprint depends on the allocation choice (rows 21 vs 22). Report it transparently.

Sheet KPI framework
A1: KPI framework - environment, circularity, economy
A2: ILLUSTRATIVE TEACHING EXAMPLE - invented numbers, not Greencolab data and not real ecoinvent factors.
A4: ID | B4: Dimension | C4: KPI | D4: Formula | E4: Unit | F4: Better if | G4: Target | H4: A: Fish monoculture | I4: C: IMTA + waste valorisation | J4: Met A | K4: Met C
A5: E1 | B5: Environment (LCA) | C5: Carbon footprint of fish | D5: Farm climate x economic share fish / kg fish | E5: kg CO2-eq/kg | F5: lower | G5: 2 | H5: =Allocation!C22 -> 2.89538 | I5: =Allocation!D22 -> 2.1248747 | J5: =IF($F5="lower",IF(H5<=$G5,1,0),IF(H5>=$G5,1,0)) -> 0 | K5: =IF($F5="lower",IF(I5<=$G5,1,0),IF(I5>=$G5,1,0)) -> 0
A6: E2 | B6: Environment (LCA) | C6: Marine eutrophication of fish | D6: Farm eutrophication x economic share fish / kg fish | E6: kg N-eq/kg | F6: lower | G6: 0.08 | H6: =Allocation!C25 -> 0.12140675 | I6: =Allocation!D25 -> 0.072483114 | J6: =IF($F6="lower",IF(H6<=$G6,1,0),IF(H6>=$G6,1,0)) -> 0 | K6: =IF($F6="lower",IF(I6<=$G6,1,0),IF(I6>=$G6,1,0)) -> 1
A7: E3 | B7: Environment (LCA) | C7: Energy demand of fish | D7: Farm energy x economic share fish / kg fish | E7: MJ/kg | F7: lower | G7: 40 | H7: =Allocation!C26 -> 45.6525 | I7: =Allocation!D26 -> 35.648862 | J7: =IF($F7="lower",IF(H7<=$G7,1,0),IF(H7>=$G7,1,0)) -> 0 | K7: =IF($F7="lower",IF(I7<=$G7,1,0),IF(I7>=$G7,1,0)) -> 1
A8: E4 | B8: Environment (LCA) | C8: Feed share of climate impact (hotspot) | D8: Climate from feed / total climate | E8: % | F8: lower | G8: 0.75 | H8: =LCIA!C25/LCIA!C24 -> 0.72788373 | I8: =LCIA!D25/LCIA!D24 -> 0.66517482 | J8: =IF($F8="lower",IF(H8<=$G8,1,0),IF(H8>=$G8,1,0)) -> 1 | K8: =IF($F8="lower",IF(I8<=$G8,1,0),IF(I8>=$G8,1,0)) -> 1
A9: C1 | B9: Circularity | C9: Nitrogen recovery rate | D9: N in seaweed + mussels / N released by fish | E9: % | F9: higher | G9: 0.15 | H9: =IFERROR('Nutrient balance'!C10/'Nutrient balance'!C9,0) -> 0 | I9: =IFERROR('Nutrient balance'!D10/'Nutrient balance'!D9,0) -> 0.18333333 | J9: =IF($F9="lower",IF(H9<=$G9,1,0),IF(H9>=$G9,1,0)) -> 0 | K9: =IF($F9="lower",IF(I9<=$G9,1,0),IF(I9>=$G9,1,0)) -> 1
A10: C2 | B10: Circularity | C10: Phosphorus recovery rate | D10: P in seaweed + mussels / P released by fish | E10: % | F10: higher | G10: 0.1 | H10: =IFERROR('Nutrient balance'!C18/'Nutrient balance'!C17,0) -> 0 | I10: =IFERROR('Nutrient balance'!D18/'Nutrient balance'!D17,0) -> 0.10576923 | J10: =IF($F10="lower",IF(H10<=$G10,1,0),IF(H10>=$G10,1,0)) -> 0 | K10: =IF($F10="lower",IF(I10<=$G10,1,0),IF(I10>=$G10,1,0)) -> 1
A11: C3 | B11: Circularity | C11: Nitrogen use efficiency | D11: N in all products / N in feed | E11: % | F11: higher | G11: 0.35 | H11: =('Nutrient balance'!C6+'Nutrient balance'!C10)/'Nutrient balance'!C5 -> 0.28571429 | I11: =('Nutrient balance'!D6+'Nutrient balance'!D10)/'Nutrient balance'!D5 -> 0.41666667 | J11: =IF($F11="lower",IF(H11<=$G11,1,0),IF(H11>=$G11,1,0)) -> 0 | K11: =IF($F11="lower",IF(I11<=$G11,1,0),IF(I11>=$G11,1,0)) -> 1
A12: C4 | B12: Circularity | C12: Feed conversion ratio | D12: kg feed / kg fish | E12: kg/kg | F12: lower | G12: 1.7 | H12: =LCI!C6/LCI!C21 -> 1.5 | I12: =LCI!D6/LCI!D21 -> 1.5 | J12: =IF($F12="lower",IF(H12<=$G12,1,0),IF(H12>=$G12,1,0)) -> 1 | K12: =IF($F12="lower",IF(I12<=$G12,1,0),IF(I12>=$G12,1,0)) -> 1
A13: C6 | B13: Circularity | C13: By-product valorisation rate | D13: (seaweed residues collected + shells valorised) / (residues generated + shells) | E13: % | F13: higher | G13: 0.5 | H13: =IFERROR((LCI!C31+LCI!C32)/(IF(LCI!C22>0,Parameters!$B$30,0)+LCI!C23*Parameters!$B$24),0) -> 0 | I13: =IFERROR((LCI!D31+LCI!D32)/(IF(LCI!D22>0,Parameters!$B$30,0)+LCI!D23*Parameters!$B$24),0) -> 1 | J13: =IF($F13="lower",IF(H13<=$G13,1,0),IF(H13>=$G13,1,0)) -> 0 | K13: =IF($F13="lower",IF(I13<=$G13,1,0),IF(I13>=$G13,1,0)) -> 1
A14: C5 | B14: Circularity | C14: Share of non-fed biomass | D14: (seaweed + mussels) / total harvest | E14: % | F14: higher | G14: 0.5 | H14: =(LCI!C22+LCI!C23)/LCI!C24 -> 0 | I14: =(LCI!D22+LCI!D23)/LCI!D24 -> 0.65217391 | J14: =IF($F14="lower",IF(H14<=$G14,1,0),IF(H14>=$G14,1,0)) -> 0 | K14: =IF($F14="lower",IF(I14<=$G14,1,0),IF(I14>=$G14,1,0)) -> 1
A15: B1 | B15: Economy | C15: Eco-efficiency | D15: Revenue / t CO2-eq | E15: EUR/t CO2-eq | F15: higher | G15: 3000 | H15: =Allocation!C16/(Allocation!C5/1000) -> 2417.6447 | I15: =Allocation!D16/(Allocation!D5/1000) -> 3294.3118 | J15: =IF($F15="lower",IF(H15<=$G15,1,0),IF(H15>=$G15,1,0)) -> 0 | K15: =IF($F15="lower",IF(I15<=$G15,1,0),IF(I15>=$G15,1,0)) -> 1
A16: B2 | B16: Economy | C16: Revenue share of extractive species | D16: (revenue seaweed + mussels) / total revenue | E16: % | F16: higher | G16: 0.25 | H16: =(Allocation!C14+Allocation!C15)/Allocation!C16 -> 0 | I16: =(Allocation!D14+Allocation!D15)/Allocation!D16 -> 0.32934132 | J16: =IF($F16="lower",IF(H16<=$G16,1,0),IF(H16>=$G16,1,0)) -> 0 | K16: =IF($F16="lower",IF(I16<=$G16,1,0),IF(I16>=$G16,1,0)) -> 1
C18: Targets met | H18: =SUM(J5:J16)&" of 12" -> 2 of 12 | I18: =SUM(K5:K16)&" of 12" -> 11 of 12
A20: Green = target met, red = not met. Targets (yellow) would be agreed with the company in a workshop.
A21: Read the dimensions together: circularity KPIs show whether the loop works; LCA KPIs show whether it really lowers impact.
A22: Check the Results tab: total farm emissions rise from A to C even when per-kg values improve; waste valorisation improves circularity KPIs but changes climate results only slightly.

Sheet Results
A1: Results summary
A2: ILLUSTRATIVE TEACHING EXAMPLE - invented numbers, not Greencolab data and not real ecoinvent factors.
A4: Indicator | B4: Unit | C4: A: Fish monoculture | D4: C: IMTA + waste valorisation | E4: Change A -> C
A5: Farm total climate change | B5: kg CO2-eq/yr | C5: =LCIA!C24 -> 115815.2 | D5: =LCIA!D24 -> 126733.6 | E5: =IFERROR(D5/C5-1,0) -> 0.094274327
A6: Farm total marine eutrophication | B6: kg N-eq/yr | C6: =LCIA!C46 -> 4856.27 | D6: =LCIA!D46 -> 4323.1 | E6: =IFERROR(D6/C6-1,0) -> -0.10979002
A7: Farm total energy demand | B7: GJ/yr | C7: =LCIA!C68/1000 -> 1826.1 | D7: =LCIA!D68/1000 -> 2126.2 | E7: =IFERROR(D7/C7-1,0) -> 0.1643393
A8: Total harvest | B8: t/yr | C8: =LCI!C24/1000 -> 40 | D8: =LCI!D24/1000 -> 115 | E8: =IFERROR(D8/C8-1,0) -> 1.875
A9: Climate change per kg fish (economic) | B9: kg CO2-eq/kg | C9: =Allocation!C22 -> 2.89538 | D9: =Allocation!D22 -> 2.1248747 | E9: =IFERROR(D9/C9-1,0) -> -0.26611542
A10: Climate change per kg fish (mass) | B10: kg CO2-eq/kg | C10: =Allocation!C21 -> 2.89538 | D10: =Allocation!D21 -> 1.1020313 | E10: =IFERROR(D10/C10-1,0) -> -0.61938284
A11: Marine eutrophication per kg fish | B11: kg N-eq/kg | C11: =Allocation!C25 -> 0.12140675 | D11: =Allocation!D25 -> 0.072483114 | E11: =IFERROR(D11/C11-1,0) -> -0.40297295
A12: Nitrogen recovery rate | B12: % | C12: =IFERROR('Nutrient balance'!C10/'Nutrient balance'!C9,0) -> 0 | D12: =IFERROR('Nutrient balance'!D10/'Nutrient balance'!D9,0) -> 0.18333333 | E12: =D12-C12 -> 0.18333333
A13: N emitted to sea | B13: kg N/yr | C13: ='Nutrient balance'!C11 -> 3000 | D13: ='Nutrient balance'!D11 -> 2450 | E13: =IFERROR(D13/C13-1,0) -> -0.18333333
A14: KPI targets met | B14: of 12 | C14: ='KPI framework'!H18 -> 2 of 12 | D14: ='KPI framework'!I18 -> 11 of 12
A16: Key messages
A17: 1. Feed dominates climate change in all scenarios (see LCIA) - the biggest lever is feed composition and FCR.
A18: 2. IMTA lowers N to the sea and eutrophication per kg fish: seaweed and mussels recover part of the fish's nutrients.
A19: 3. Total farm emissions rise from A to C (boats, ropes, electricity, transport) while per-kg values fall: absolute vs relative trade-off.
A20: 5. Waste valorisation in C: collecting seaweed residues raises N recovery and shells replace limestone - circularity KPIs improve clearly; its climate effect is small (+460 / -400 kg CO2-eq)
A21: 4. The fish footprint changes with the allocation method (economic vs mass): a methodological choice to report transparently.
A22: Compare with your openLCA result (scenario B, 1 kg sea bream, economic allocation)
A23: Indicator | B23: Unit | C23: This workbook (B) | D23: Your openLCA (B) | E23: Difference
A24: Climate change per kg fish | B24: kg CO2-eq/kg | C24: =D9 -> 2.1248747 | D24: ='openLCA results'!D6 -> 1.8256402 | E24: =IF(D24="","paste openLCA value",D24/C24-1) -> -0.14082456
A25: Marine eutrophication per kg fish | B25: kg N-eq/kg | C25: =D11 -> 0.072483114 | D25: ='openLCA results'!D10 -> 0.0095080383 | E25: =IF(D25="","paste openLCA value",D25/C25-1) -> -0.86882409
A27: Expect differences: this workbook uses invented factors; openLCA uses ecoinvent and EF characterisation factors.

Sheet openLCA results
A1: Real openLCA results - scenario B (ecoinvent 3.7 cut-off, EF 3.1, economic allocation)
A2: Exported from openLCA on 2026-10-23. Reference: 40,000 kg sea bream (1 year). Unlike the other tabs, these are database results.
A4: Impact assessment results
A5: Impact category | B5: Unit | C5: Farm total (40 t fish/yr) | D5: Per kg sea bream | E5: Note
A6: Climate change | B6: kg CO2 eq | C6: 73025.607 | D6: =C6/40000 -> 1.8256402
A7: Climate change (fossil) | B7: kg CO2 eq | C7: 52055.941 | D7: =C7/40000 -> 1.3013985
A8: Climate change (land use) | B8: kg CO2 eq | C8: 20928.14 | D8: =C8/40000 -> 0.52320349 | E8: Mostly deforestation for soybean (BR)
A9: Climate change (biogenic) | B9: kg CO2 eq | C9: 41.527149 | D9: =C9/40000 -> 0.0010381787
A10: Eutrophication marine | B10: kg N eq | C10: 380.32153 | D10: =C10/40000 -> 0.0095080383 | E10: Farm N emission not characterised - see check below
A11: Eutrophication freshwater | B11: kg P eq | C11: 27.123281 | D11: =C11/40000 -> 0.00067808203
A12: Eutrophication terrestrial | B12: mol N eq | C12: 1997.9287 | D12: =C12/40000 -> 0.049948217
A13: Acidification | B13: mol H+ eq | C13: 581.77719 | D13: =C13/40000 -> 0.01454443
A14: Particulate matter | B14: disease incidence | C14: 0.0052598248 | D14: =C14/40000 -> 1.3149562e-07
A15: Land use | B15: dimensionless (pt) | C15: 3758913.4 | D15: =C15/40000 -> 93.972835
A16: Water use | B16: m3 world eq | C16: 102628.37 | D16: =C16/40000 -> 2.5657092
A17: Resource use fossils | B17: MJ (net calorific) | C17: 591359.27 | D17: =C17/40000 -> 14.783982
A18: Resource use minerals and metals | B18: kg Sb eq | C18: 1.7942098 | D18: =C18/40000 -> 4.4855244e-05
A19: Ozone depletion | B19: kg CFC11 eq | C19: 0.0068085003 | D19: =C19/40000 -> 1.7021251e-07
A20: Photochemical ozone formation (human health) | B20: kg NMVOC eq | C20: 245.02941 | D20: =C20/40000 -> 0.0061257353
A21: Ionising radiation (human health) | B21: kBq U235 eq | C21: 2382.1475 | D21: =C21/40000 -> 0.059553688
A22: Ecotoxicity freshwater | B22: CTUe | C22: 1381154.7 | D22: =C22/40000 -> 34.528867
... A24: Human toxicity non-cancer | B24: CTUh | C24: 0.0017733611 | D24: =C24/40000 -> 4.4334027e-08
A26: Contribution analysis: Climate change (grouped by type of process)
A27: Contributor group | B27: Farm total | C27: Share | D27: Per kg fish
A28: Land use change (crops for feed) | B28: 21685.66 | C28: =B28/SUM(B$28:B$36) -> 0.29695961 | D28: =B28/40000 -> 0.5421415
A29: Fuels and heat | B29: 13306.96 | C29: =B29/SUM(B$28:B$36) -> 0.18222317 | D29: =B29/40000 -> 0.332674
A30: Transport | B30: 8935.07 | C30: =B30/SUM(B$28:B$36) -> 0.12235528 | D30: =B30/40000 -> 0.22337675
A31: Crop farming (feed ingredients) | B31: 8432.86 | C31: =B31/SUM(B$28:B$36) -> 0.1154781 | D31: =B31/40000 -> 0.2108215
A32: Electricity generation | B32: 7432.54 | C32: =B32/SUM(B$28:B$36) -> 0.1017799 | D32: =B32/40000 -> 0.1858135
A33: IMTA farm (direct: boat CO2, N, P) | B33: 7122.4 | C33: =B33/SUM(B$28:B$36) -> 0.097532893 | D33: =B33/40000 -> 0.17806
A34: Other background processes | B34: 3681.24 | C34: =B34/SUM(B$28:B$36) -> 0.050410253 | D34: =B34/40000 -> 0.092031
A35: Fishing and fishmeal processing | B35: 1359.28 | C35: =B35/SUM(B$28:B$36) -> 0.018613741 | D35: =B35/40000 -> 0.033982
A36: Plastics and chemicals | B36: 1069.61 | C36: =B36/SUM(B$28:B$36) -> 0.014647051 | D36: =B36/40000 -> 0.02674025
A37: Total | B37: =SUM(B28:B36) -> 73025.62
A40: Contribution analysis: Eutrophication marine (grouped by type of process)
A41: Contributor group | B41: Farm total | C41: Share | D41: Per kg fish
A42: Crop farming (feed ingredients) | B42: 317.94 | C42: =B42/SUM(B$42:B$49) -> 0.83600221 | D42: =B42/40000 -> 0.0079485
A43: Transport | B43: 20.35 | C43: =B43/SUM(B$42:B$49) -> 0.05350898 | D43: =B43/40000 -> 0.00050875
A44: Fuels and heat | B44: 14.73 | C44: =B44/SUM(B$42:B$49) -> 0.038731561 | D44: =B44/40000 -> 0.00036825
A45: Fishing and fishmeal processing | B45: 13.09 | C45: =B45/SUM(B$42:B$49) -> 0.03441929 | D45: =B45/40000 -> 0.00032725
...

Sheet Sources
A1: Literature to check the illustrative values against
A2: ILLUSTRATIVE TEACHING EXAMPLE - invented numbers, not Greencolab data and not real ecoinvent factors.
A4: Reference | B4: What it supports | C4: Link
A5: Hala, Chougule et al. (2024). Life cycle assessment of integrated multi-trophic aquaculture: a review on methodology and challenges. Aquaculture 590, 741035. | B5: Functional unit and multi-product challenges in IMTA; feeds, effluents and energy as main contributors. | C5: https://aquahoy.com/life-cycle-assessment-integrated-multi-trophic-aquaculture/
A6: Garcia Garcia et al. (2016). Life Cycle Assessment of Gilthead Seabream Production in Offshore Fish Farms. Sustainability 8(12), 1228. | B6: FCR of about 2 (1.7 tested); feed and vessel fuel as hotspots. | C6: https://www.mdpi.com/2071-1050/8/12/1228
A7: Nederlof et al. (2021), Reviews in Aquaculture; summary by Global Seafood Alliance (2022). | B7: Nutrient retention in fish and recovery by extractive species in open vs closed IMTA. | C7: https://www.globalseafood.org/advocate/nutrient-retention-efficiencies-in-integrated-multi-trophic-aquaculture/
A8: Kallitsis, E. & Avramidis, P. (2025). Life cycle assessment of aquaculture production in Greece. Cleaner Environmental Systems. | B8: Gilthead sea bream 2.27 kg CO2-eq/kg (cradle-to-gate); feed up to 79% of GHG; fry production energy-intensive. | C8: https://www.mispeces.com/en/news/Greek-Aquaculture-Life-Cycle-Assessment-Highlights-Key-Areas-for-Improvement-and-Opportunities/
A9: Zoli, M. et al. (2023). Quantification and characterization of the environmental impact of sea bream and sea bass production in Italy. Cleaner Environmental Systems 9, 100118. | B9: Feed at least 60% of most impact categories; marine eutrophication driven by nutrient emissions. | C9: https://doaj.org/article/0c047700b22741bdb3ae6e5e47b07298
A10: Azizi, G. et al. (2020). Growth weight and reproductive cycle in the mussel (Mytilus galloprovincialis) from Cala Iris, Morocco. EasyChair Preprint 2857. | B10: Rough check of shell share of mussel weight (about one third; data partly inconsistent). | C10: https://easychair.org/publications/preprint/P5vQ/open
A12: IMPORTANT: most activity data, nutrient contents, prices and all factors in this workbook are illustrative assumptions. Only the values marked 'Checked vs' were compared with the literature above, and several differ from it. Real impact results are in the 'openLCA results' tab.
